2025-09-17 17:44:49 - app - INFO - __init__.py:23 - 🚀 로깅 설정 완료
2025-09-17 17:44:49 - app - INFO - __init__.py:24 - 📁 로그 디렉토리: C:\workspace\side\ai-agent\ai-interface\app\data\logs
2025-09-17 17:48:04 - app - INFO - __init__.py:23 - 로깅 설정 완료
2025-09-17 17:48:04 - app - INFO - __init__.py:24 - 로그 디렉토리: C:\workspace\side\ai-agent\ai-interface\app\data\logs
2025-09-17 17:49:45 - app - INFO - __init__.py:23 - 로깅 설정 완료
2025-09-17 17:49:45 - app - INFO - __init__.py:24 - 로그 디렉토리: C:\workspace\side\ai-agent\ai-interface\app\data\logs
2025-09-18 09:02:33 - app - INFO - __init__.py:23 - 로깅 설정 완료
2025-09-18 09:02:33 - app - INFO - __init__.py:24 - 로그 디렉토리: C:\workspace\side\ai-agent\ai-interface\app\data\logs
2025-09-19 17:57:03 - app - INFO - __init__.py:23 - 로깅 설정 완료
2025-09-19 17:57:03 - app - INFO - __init__.py:24 - 로그 디렉토리: C:\workspace\side\ai-agent\ai-interface\app\data\logs
2025-09-19 17:57:04 - app.infra.docker.client - INFO - client.py:32 - Docker 클라이언트 초기화 완료
2025-09-22 10:25:54 - app - INFO - __init__.py:23 - 로깅 설정 완료
2025-09-22 10:25:54 - app - INFO - __init__.py:24 - 로그 디렉토리: C:\workspace\side\ai-agent\ai-interface\app\data\logs
2025-09-22 10:25:54 - app.infra.docker.client - WARNING - client.py:34 - Docker 초기화 실패: Error while fetching server API version: (2, 'CreateFile', '지정된 파일을 찾을 수 없습니다.')
2025-09-22 10:28:42 - app - INFO - __init__.py:23 - 로깅 설정 완료
2025-09-22 10:28:42 - app - INFO - __init__.py:24 - 로그 디렉토리: C:\workspace\side\ai-agent\ai-interface\app\data\logs
2025-09-22 10:28:42 - app.infra.docker.client - WARNING - client.py:34 - Docker 초기화 실패: Error while fetching server API version: (2, 'CreateFile', '지정된 파일을 찾을 수 없습니다.')
2025-09-22 10:29:27 - app.domains.file.service - INFO - service.py:45 - 파일 처리 시작: 질의응답_Sample.xlsx, 크기: 12080 bytes, 해시: 2662de4186e88210...
2025-09-22 10:30:05 - app.domains.file.service - ERROR - service.py:74 - 예상치 못한 오류: FileExtractor.extract_excel_content() got an unexpected keyword argument 'encoding'
2025-09-22 10:30:17 - app.domains.file.service - INFO - service.py:45 - 파일 처리 시작: 질의응답_Sample.xlsx, 크기: 12080 bytes, 해시: 2662de4186e88210...
2025-09-22 10:30:35 - app.domains.file.service - ERROR - service.py:74 - 예상치 못한 오류: FileExtractor.extract_excel_content() got an unexpected keyword argument 'encoding'
2025-09-22 10:30:44 - app.domains.file.service - INFO - service.py:45 - 파일 처리 시작: 질의응답_Sample.xlsx, 크기: 12080 bytes, 해시: 2662de4186e88210...
2025-09-22 10:31:32 - app.domains.file.service - ERROR - service.py:74 - 예상치 못한 오류: FileExtractor.extract_excel_content() got an unexpected keyword argument 'encoding'
2025-09-22 10:32:38 - app - INFO - __init__.py:23 - 로깅 설정 완료
2025-09-22 10:32:38 - app - INFO - __init__.py:24 - 로그 디렉토리: C:\workspace\side\ai-agent\ai-interface\app\data\logs
2025-09-22 10:32:38 - app.infra.docker.client - WARNING - client.py:34 - Docker 초기화 실패: Error while fetching server API version: (2, 'CreateFile', '지정된 파일을 찾을 수 없습니다.')
2025-09-22 10:32:55 - app.domains.file.service - INFO - service.py:45 - 파일 처리 시작: 질의응답_Sample.xlsx, 크기: 12080 bytes, 해시: 2662de4186e88210...
2025-09-22 10:32:57 - app.domains.file.service - ERROR - service.py:74 - 예상치 못한 오류: FileExtractor.extract_excel_content() got an unexpected keyword argument 'encoding'
2025-09-22 10:33:04 - app.domains.file.service - INFO - service.py:45 - 파일 처리 시작: 질의응답_Sample.xlsx, 크기: 12080 bytes, 해시: 2662de4186e88210...
2025-09-22 10:34:26 - app.domains.file.service - INFO - service.py:64 - 파일 처리 완료: 질의응답_Sample.xlsx
2025-09-22 10:35:18 - app.domains.file.service - INFO - service.py:45 - 파일 처리 시작: test.txt, 크기: 88 bytes, 해시: 7d2614aa5420e29a...
2025-09-22 10:35:18 - app.domains.file.service - INFO - service.py:64 - 파일 처리 완료: test.txt
2025-09-22 10:35:50 - app.domains.file.service - INFO - service.py:45 - 파일 처리 시작: 사회적책임과거버넌스.txt, 크기: 290 bytes, 해시: 5084136a63426828...
2025-09-22 10:35:50 - app.domains.file.service - INFO - service.py:64 - 파일 처리 완료: 사회적책임과거버넌스.txt
2025-09-22 10:36:12 - app.domains.file.service - INFO - service.py:45 - 파일 처리 시작: 사회적책임과거버넌스.txt, 크기: 290 bytes, 해시: 5084136a63426828...
2025-09-22 10:36:12 - app.domains.file.service - INFO - service.py:45 - 파일 처리 시작: ai_service_module_작업.xlsx, 크기: 11802 bytes, 해시: 5802b60cd7809ca6...
2025-09-22 10:36:12 - app.domains.file.service - INFO - service.py:64 - 파일 처리 완료: 사회적책임과거버넌스.txt
2025-09-22 10:36:12 - app.domains.file.service - INFO - service.py:64 - 파일 처리 완료: ai_service_module_작업.xlsx
2025-09-22 10:36:12 - app.domains.file.service - ERROR - service.py:114 - 다중 파일 처리 오류: 'TextExtractionResult' object does not support item assignment
2025-09-22 10:37:00 - app.domains.file.service - INFO - service.py:45 - 파일 처리 시작: 사회적책임과거버넌스.txt, 크기: 290 bytes, 해시: 5084136a63426828...
2025-09-22 10:37:00 - app.domains.file.service - INFO - service.py:45 - 파일 처리 시작: ai_service_module_작업.xlsx, 크기: 11802 bytes, 해시: 5802b60cd7809ca6...
2025-09-22 10:37:18 - app.domains.file.service - INFO - service.py:64 - 파일 처리 완료: 사회적책임과거버넌스.txt
2025-09-22 10:37:43 - app.domains.file.service - INFO - service.py:64 - 파일 처리 완료: ai_service_module_작업.xlsx
2025-09-22 10:38:17 - app.domains.file.service - ERROR - service.py:114 - 다중 파일 처리 오류: 'TextExtractionResult' object does not support item assignment
2025-09-22 10:40:13 - app - INFO - __init__.py:23 - 로깅 설정 완료
2025-09-22 10:40:13 - app - INFO - __init__.py:24 - 로그 디렉토리: C:\workspace\side\ai-agent\ai-interface\app\data\logs
2025-09-22 10:40:13 - app.infra.docker.client - WARNING - client.py:34 - Docker 초기화 실패: Error while fetching server API version: (2, 'CreateFile', '지정된 파일을 찾을 수 없습니다.')
2025-09-22 10:40:18 - app.domains.file.service - INFO - service.py:45 - 파일 처리 시작: 사회적책임과거버넌스.txt, 크기: 290 bytes, 해시: 5084136a63426828...
2025-09-22 10:40:18 - app.domains.file.service - INFO - service.py:45 - 파일 처리 시작: ai_service_module_작업.xlsx, 크기: 11802 bytes, 해시: 5802b60cd7809ca6...
2025-09-22 10:40:18 - app.domains.file.service - INFO - service.py:64 - 파일 처리 완료: 사회적책임과거버넌스.txt
2025-09-22 10:40:18 - app.domains.file.service - INFO - service.py:64 - 파일 처리 완료: ai_service_module_작업.xlsx
2025-09-22 10:42:37 - app - INFO - __init__.py:23 - 로깅 설정 완료
2025-09-22 10:42:37 - app - INFO - __init__.py:24 - 로그 디렉토리: C:\workspace\side\ai-agent\ai-interface\app\data\logs
2025-09-22 10:42:37 - app.infra.docker.client - WARNING - client.py:34 - Docker 초기화 실패: Error while fetching server API version: (2, 'CreateFile', '지정된 파일을 찾을 수 없습니다.')
2025-09-22 10:44:39 - app - INFO - __init__.py:23 - 로깅 설정 완료
2025-09-22 10:44:39 - app - INFO - __init__.py:24 - 로그 디렉토리: C:\workspace\side\ai-agent\ai-interface\app\data\logs
2025-09-22 10:44:39 - app.infra.docker.client - WARNING - client.py:34 - Docker 초기화 실패: Error while fetching server API version: (2, 'CreateFile', '지정된 파일을 찾을 수 없습니다.')
2025-09-22 10:44:50 - app.domains.file.service - INFO - service.py:45 - 파일 처리 시작: 사회적책임과거버넌스.txt, 크기: 290 bytes, 해시: 5084136a63426828...
2025-09-22 10:44:50 - app.domains.file.service - INFO - service.py:45 - 파일 처리 시작: ai_service_module_작업.xlsx, 크기: 11802 bytes, 해시: 5802b60cd7809ca6...
2025-09-22 10:44:50 - app.domains.file.service - INFO - service.py:64 - 파일 처리 완료: 사회적책임과거버넌스.txt
2025-09-22 10:44:51 - app.domains.file.service - INFO - service.py:64 - 파일 처리 완료: ai_service_module_작업.xlsx
2025-09-22 10:45:06 - app.domains.file.service - INFO - service.py:45 - 파일 처리 시작: 사회적책임과거버넌스.txt, 크기: 290 bytes, 해시: 5084136a63426828...
2025-09-22 10:45:06 - app.domains.file.service - INFO - service.py:45 - 파일 처리 시작: ai_service_module_작업.xlsx, 크기: 11802 bytes, 해시: 5802b60cd7809ca6...
2025-09-22 10:45:06 - app.domains.file.service - INFO - service.py:64 - 파일 처리 완료: 사회적책임과거버넌스.txt
2025-09-22 10:45:06 - app.domains.file.service - INFO - service.py:64 - 파일 처리 완료: ai_service_module_작업.xlsx
2025-09-22 10:45:43 - app - INFO - __init__.py:23 - 로깅 설정 완료
2025-09-22 10:45:43 - app - INFO - __init__.py:24 - 로그 디렉토리: C:\workspace\side\ai-agent\ai-interface\app\data\logs
2025-09-22 10:45:43 - app.infra.docker.client - WARNING - client.py:34 - Docker 초기화 실패: Error while fetching server API version: (2, 'CreateFile', '지정된 파일을 찾을 수 없습니다.')
2025-09-22 10:45:50 - app.domains.file.service - INFO - service.py:45 - 파일 처리 시작: 사회적책임과거버넌스.txt, 크기: 290 bytes, 해시: 5084136a63426828...
2025-09-22 10:45:50 - app.domains.file.service - INFO - service.py:45 - 파일 처리 시작: ai_service_module_작업.xlsx, 크기: 11802 bytes, 해시: 5802b60cd7809ca6...
2025-09-22 10:45:50 - app.domains.file.service - INFO - service.py:64 - 파일 처리 완료: 사회적책임과거버넌스.txt
2025-09-22 10:45:50 - app.domains.file.service - INFO - service.py:64 - 파일 처리 완료: ai_service_module_작업.xlsx
2025-09-22 10:55:46 - app - INFO - __init__.py:23 - 로깅 설정 완료
2025-09-22 10:55:46 - app - INFO - __init__.py:24 - 로그 디렉토리: C:\workspace\side\ai-agent\ai-interface\app\data\logs
2025-09-22 10:55:46 - app.infra.docker.client - WARNING - client.py:34 - Docker 초기화 실패: Error while fetching server API version: (2, 'CreateFile', '지정된 파일을 찾을 수 없습니다.')
2025-09-22 11:00:07 - app - INFO - __init__.py:23 - 로깅 설정 완료
2025-09-22 11:00:07 - app - INFO - __init__.py:24 - 로그 디렉토리: C:\workspace\side\ai-agent\ai-interface\app\data\logs
2025-09-22 11:00:07 - app.infra.docker.client - WARNING - client.py:34 - Docker 초기화 실패: Error while fetching server API version: (2, 'CreateFile', '지정된 파일을 찾을 수 없습니다.')
2025-09-22 11:24:20 - app - INFO - __init__.py:23 - 로깅 설정 완료
2025-09-22 11:24:20 - app - INFO - __init__.py:24 - 로그 디렉토리: C:\workspace\side\ai-agent\ai-interface\app\data\logs
2025-09-22 11:24:20 - app.infra.docker.client - WARNING - client.py:34 - Docker 초기화 실패: Error while fetching server API version: (2, 'CreateFile', '지정된 파일을 찾을 수 없습니다.')
2025-09-22 11:29:22 - app - INFO - __init__.py:23 - 로깅 설정 완료
2025-09-22 11:29:22 - app - INFO - __init__.py:24 - 로그 디렉토리: C:\workspace\side\ai-agent\ai-interface\app\data\logs
2025-09-22 11:29:22 - app.infra.docker.client - WARNING - client.py:34 - Docker 초기화 실패: Error while fetching server API version: (2, 'CreateFile', '지정된 파일을 찾을 수 없습니다.')
2025-09-22 13:08:20 - app - INFO - __init__.py:23 - 로깅 설정 완료
2025-09-22 13:08:20 - app - INFO - __init__.py:24 - 로그 디렉토리: C:\workspace\side\ai-agent\ai-interface\app\data\logs
2025-09-22 13:08:20 - app.infra.docker.client - WARNING - client.py:34 - Docker 초기화 실패: Error while fetching server API version: (2, 'CreateFile', '지정된 파일을 찾을 수 없습니다.')
2025-09-22 13:13:19 - app - INFO - __init__.py:23 - 로깅 설정 완료
2025-09-22 13:13:19 - app - INFO - __init__.py:24 - 로그 디렉토리: C:\workspace\side\ai-agent\ai-interface\app\data\logs
2025-09-22 13:13:19 - app.infra.docker.client - WARNING - client.py:34 - Docker 초기화 실패: Error while fetching server API version: (2, 'CreateFile', '지정된 파일을 찾을 수 없습니다.')
2025-09-22 13:14:30 - app - INFO - __init__.py:23 - 로깅 설정 완료
2025-09-22 13:14:30 - app - INFO - __init__.py:24 - 로그 디렉토리: C:\workspace\side\ai-agent\ai-interface\app\data\logs
2025-09-22 13:14:30 - app.infra.docker.client - WARNING - client.py:34 - Docker 초기화 실패: Error while fetching server API version: (2, 'CreateFile', '지정된 파일을 찾을 수 없습니다.')
2025-09-22 13:45:51 - app - INFO - __init__.py:23 - 로깅 설정 완료
2025-09-22 13:45:51 - app - INFO - __init__.py:24 - 로그 디렉토리: C:\workspace\side\ai-agent\ai-interface\app\data\logs
2025-09-22 13:45:51 - app.infra.docker.client - WARNING - client.py:34 - Docker 초기화 실패: Error while fetching server API version: (2, 'CreateFile', '지정된 파일을 찾을 수 없습니다.')
2025-09-22 13:46:07 - app.infra.ai.prompt.prompt_manager - WARNING - prompt_manager.py:34 - System prompts directory not found: C:\workspace\side\ai-agent\ai-interface\app\prompts\system
2025-09-22 13:50:12 - app - INFO - __init__.py:23 - 로깅 설정 완료
2025-09-22 13:50:12 - app - INFO - __init__.py:24 - 로그 디렉토리: C:\workspace\side\ai-agent\ai-interface\app\data\logs
2025-09-22 13:50:12 - app.infra.docker.client - WARNING - client.py:34 - Docker 초기화 실패: Error while fetching server API version: (2, 'CreateFile', '지정된 파일을 찾을 수 없습니다.')
2025-09-22 13:58:06 - app - INFO - __init__.py:23 - 로깅 설정 완료
2025-09-22 13:58:06 - app - INFO - __init__.py:24 - 로그 디렉토리: C:\workspace\side\ai-agent\ai-interface\app\data\logs
2025-09-22 13:58:06 - app.infra.docker.client - WARNING - client.py:34 - Docker 초기화 실패: Error while fetching server API version: (2, 'CreateFile', '지정된 파일을 찾을 수 없습니다.')
2025-09-22 13:58:16 - app.infra.ai.prompt.prompt_manager - INFO - prompt_manager.py:52 - Loaded 1 system prompts from C:\workspace\side\ai-agent\ai-interface\prompts\system
2025-09-22 14:00:00 - app - INFO - __init__.py:23 - 로깅 설정 완료
2025-09-22 14:00:00 - app - INFO - __init__.py:24 - 로그 디렉토리: C:\workspace\side\ai-agent\ai-interface\app\data\logs
2025-09-22 14:00:00 - app.infra.docker.client - WARNING - client.py:34 - Docker 초기화 실패: Error while fetching server API version: (2, 'CreateFile', '지정된 파일을 찾을 수 없습니다.')
2025-09-22 14:00:20 - app.infra.ai.prompt.prompt_manager - INFO - prompt_manager.py:52 - Loaded 1 system prompts from C:\workspace\side\ai-agent\ai-interface\prompts\system
2025-09-22 14:03:48 - app - INFO - __init__.py:23 - 로깅 설정 완료
2025-09-22 14:03:48 - app - INFO - __init__.py:24 - 로그 디렉토리: C:\workspace\side\ai-agent\ai-interface\app\data\logs
2025-09-22 14:03:48 - app.infra.docker.client - WARNING - client.py:34 - Docker 초기화 실패: Error while fetching server API version: (2, 'CreateFile', '지정된 파일을 찾을 수 없습니다.')
2025-09-22 14:16:52 - app.infra.ai.prompt.prompt_manager - INFO - prompt_manager.py:52 - Loaded 1 system prompts from C:\workspace\side\ai-agent\ai-interface\prompts\system
2025-09-22 14:17:10 - app - INFO - __init__.py:23 - 로깅 설정 완료
2025-09-22 14:17:10 - app - INFO - __init__.py:24 - 로그 디렉토리: C:\workspace\side\ai-agent\ai-interface\app\data\logs
2025-09-22 14:17:10 - app.infra.docker.client - WARNING - client.py:34 - Docker 초기화 실패: Error while fetching server API version: (2, 'CreateFile', '지정된 파일을 찾을 수 없습니다.')
2025-09-22 14:17:12 - app.infra.ai.prompt.prompt_manager - INFO - prompt_manager.py:52 - Loaded 1 system prompts from C:\workspace\side\ai-agent\ai-interface\prompts\system
2025-09-22 14:17:27 - app - INFO - __init__.py:23 - 로깅 설정 완료
2025-09-22 14:17:27 - app - INFO - __init__.py:24 - 로그 디렉토리: C:\workspace\side\ai-agent\ai-interface\app\data\logs
2025-09-22 14:17:27 - app.infra.docker.client - WARNING - client.py:34 - Docker 초기화 실패: Error while fetching server API version: (2, 'CreateFile', '지정된 파일을 찾을 수 없습니다.')
2025-09-22 14:17:27 - app.infra.ai.prompt.prompt_manager - INFO - prompt_manager.py:52 - Loaded 1 system prompts from C:\workspace\side\ai-agent\ai-interface\prompts\system
2025-09-22 14:22:26 - app - INFO - __init__.py:23 - 로깅 설정 완료
2025-09-22 14:22:26 - app - INFO - __init__.py:24 - 로그 디렉토리: C:\workspace\side\ai-agent\ai-interface\app\data\logs
2025-09-22 14:22:26 - app.infra.docker.client - WARNING - client.py:34 - Docker 초기화 실패: Error while fetching server API version: (2, 'CreateFile', '지정된 파일을 찾을 수 없습니다.')
2025-09-22 14:22:26 - app.infra.ai.prompt.prompt_manager - INFO - prompt_manager.py:52 - Loaded 1 system prompts from C:\workspace\side\ai-agent\ai-interface\prompts\system
2025-09-22 14:27:25 - app - INFO - __init__.py:23 - 로깅 설정 완료
2025-09-22 14:27:25 - app - INFO - __init__.py:24 - 로그 디렉토리: C:\workspace\side\ai-agent\ai-interface\app\data\logs
2025-09-22 14:27:25 - app.infra.docker.client - WARNING - client.py:34 - Docker 초기화 실패: Error while fetching server API version: (2, 'CreateFile', '지정된 파일을 찾을 수 없습니다.')
2025-09-22 14:27:25 - app.infra.ai.prompt.prompt_manager - INFO - prompt_manager.py:52 - Loaded 1 system prompts from C:\workspace\side\ai-agent\ai-interface\prompts\system
2025-09-22 14:32:28 - app - INFO - __init__.py:23 - 로깅 설정 완료
2025-09-22 14:32:28 - app - INFO - __init__.py:24 - 로그 디렉토리: C:\workspace\side\ai-agent\ai-interface\app\data\logs
2025-09-22 14:32:28 - app.infra.docker.client - WARNING - client.py:34 - Docker 초기화 실패: Error while fetching server API version: (2, 'CreateFile', '지정된 파일을 찾을 수 없습니다.')
2025-09-22 14:32:28 - app.infra.ai.prompt.prompt_manager - INFO - prompt_manager.py:52 - Loaded 1 system prompts from C:\workspace\side\ai-agent\ai-interface\prompts\system
2025-09-22 14:37:30 - app - INFO - __init__.py:23 - 로깅 설정 완료
2025-09-22 14:37:30 - app - INFO - __init__.py:24 - 로그 디렉토리: C:\workspace\side\ai-agent\ai-interface\app\data\logs
2025-09-22 14:37:30 - app.infra.docker.client - WARNING - client.py:34 - Docker 초기화 실패: Error while fetching server API version: (2, 'CreateFile', '지정된 파일을 찾을 수 없습니다.')
2025-09-22 14:37:30 - app.infra.ai.prompt.prompt_manager - INFO - prompt_manager.py:52 - Loaded 1 system prompts from C:\workspace\side\ai-agent\ai-interface\prompts\system
2025-09-22 14:42:31 - app - INFO - __init__.py:23 - 로깅 설정 완료
2025-09-22 14:42:31 - app - INFO - __init__.py:24 - 로그 디렉토리: C:\workspace\side\ai-agent\ai-interface\app\data\logs
2025-09-22 14:42:31 - app.infra.docker.client - WARNING - client.py:34 - Docker 초기화 실패: Error while fetching server API version: (2, 'CreateFile', '지정된 파일을 찾을 수 없습니다.')
2025-09-22 14:42:31 - app.infra.ai.prompt.prompt_manager - INFO - prompt_manager.py:52 - Loaded 1 system prompts from C:\workspace\side\ai-agent\ai-interface\prompts\system
2025-09-22 14:43:41 - app - INFO - __init__.py:23 - 로깅 설정 완료
2025-09-22 14:43:41 - app - INFO - __init__.py:24 - 로그 디렉토리: C:\workspace\side\ai-agent\ai-interface\app\data\logs
2025-09-22 14:43:41 - app.infra.docker.client - WARNING - client.py:34 - Docker 초기화 실패: Error while fetching server API version: (2, 'CreateFile', '지정된 파일을 찾을 수 없습니다.')
2025-09-22 14:43:41 - app.infra.ai.prompt.prompt_manager - INFO - prompt_manager.py:52 - Loaded 1 system prompts from C:\workspace\side\ai-agent\ai-interface\prompts\system
2025-09-22 14:48:57 - app - INFO - __init__.py:23 - 로깅 설정 완료
2025-09-22 14:48:57 - app - INFO - __init__.py:24 - 로그 디렉토리: C:\workspace\side\ai-agent\ai-interface\app\data\logs
2025-09-22 14:48:57 - app.infra.docker.client - WARNING - client.py:34 - Docker 초기화 실패: Error while fetching server API version: (2, 'CreateFile', '지정된 파일을 찾을 수 없습니다.')
2025-09-22 14:48:57 - app.infra.ai.prompt.prompt_manager - INFO - prompt_manager.py:52 - Loaded 1 system prompts from C:\workspace\side\ai-agent\ai-interface\prompts\system
2025-09-22 14:57:14 - app - INFO - __init__.py:23 - 로깅 설정 완료
2025-09-22 14:57:14 - app - INFO - __init__.py:24 - 로그 디렉토리: C:\workspace\side\ai-agent\ai-interface\app\data\logs
2025-09-22 14:57:14 - app.infra.docker.client - WARNING - client.py:34 - Docker 초기화 실패: Error while fetching server API version: (2, 'CreateFile', '지정된 파일을 찾을 수 없습니다.')
2025-09-22 14:57:14 - app.infra.ai.prompt.prompt_manager - INFO - prompt_manager.py:52 - Loaded 1 system prompts from C:\workspace\side\ai-agent\ai-interface\prompts\system
2025-09-22 14:58:12 - app.domains.llm.service - ERROR - service.py:55 - 채팅 요청 검증 오류: Failed to get system prompt: Domain 'example' not found
2025-09-22 15:02:46 - app - INFO - __init__.py:23 - 로깅 설정 완료
2025-09-22 15:02:46 - app - INFO - __init__.py:24 - 로그 디렉토리: C:\workspace\side\ai-agent\ai-interface\app\data\logs
2025-09-22 15:02:46 - app.infra.docker.client - WARNING - client.py:34 - Docker 초기화 실패: Error while fetching server API version: (2, 'CreateFile', '지정된 파일을 찾을 수 없습니다.')
2025-09-22 15:02:46 - app.infra.ai.prompt.prompt_manager - INFO - prompt_manager.py:52 - Loaded 2 system prompts from C:\workspace\side\ai-agent\ai-interface\prompts\system
2025-09-22 15:04:48 - app.infra.ai.llm.llm_manager - ERROR - llm_manager.py:62 - Failed to generate response: Cannot connect to host localhost:11434 ssl:default [Multiple exceptions: [Errno 10061] Connect call failed ('::1', 11434, 0, 0), [Errno 10061] Connect call failed ('127.0.0.1', 11434)]
2025-09-22 15:04:48 - app.domains.llm.service - ERROR - service.py:58 - LLM 응답 생성 오류: Failed to generate response: Cannot connect to host localhost:11434 ssl:default [Multiple exceptions: [Errno 10061] Connect call failed ('::1', 11434, 0, 0), [Errno 10061] Connect call failed ('127.0.0.1', 11434)]
2025-09-22 15:29:57 - app - INFO - __init__.py:23 - 로깅 설정 완료
2025-09-22 15:29:57 - app - INFO - __init__.py:24 - 로그 디렉토리: C:\workspace\side\ai-agent\ai-interface\app\data\logs
2025-09-22 15:29:57 - app.infra.docker.client - WARNING - client.py:34 - Docker 초기화 실패: Error while fetching server API version: (2, 'CreateFile', '지정된 파일을 찾을 수 없습니다.')
2025-09-22 15:29:57 - app.infra.ai.prompt.prompt_manager - INFO - prompt_manager.py:52 - Loaded 2 system prompts from C:\workspace\side\ai-agent\ai-interface\prompts\system
2025-09-22 15:31:16 - app - INFO - __init__.py:23 - 로깅 설정 완료
2025-09-22 15:31:16 - app - INFO - __init__.py:24 - 로그 디렉토리: C:\workspace\side\ai-agent\ai-interface\app\data\logs
2025-09-22 15:31:16 - app.infra.docker.client - WARNING - client.py:34 - Docker 초기화 실패: Error while fetching server API version: (2, 'CreateFile', '지정된 파일을 찾을 수 없습니다.')
2025-09-22 15:31:16 - app.infra.ai.prompt.prompt_manager - INFO - prompt_manager.py:52 - Loaded 2 system prompts from C:\workspace\side\ai-agent\ai-interface\prompts\system
2025-09-22 15:35:19 - app - INFO - __init__.py:23 - 로깅 설정 완료
2025-09-22 15:35:19 - app - INFO - __init__.py:24 - 로그 디렉토리: C:\workspace\side\ai-agent\ai-interface\app\data\logs
2025-09-22 15:35:19 - app.infra.docker.client - WARNING - client.py:34 - Docker 초기화 실패: Error while fetching server API version: (2, 'CreateFile', '지정된 파일을 찾을 수 없습니다.')
2025-09-22 15:35:19 - app.infra.ai.prompt.prompt_manager - INFO - prompt_manager.py:52 - Loaded 2 system prompts from C:\workspace\side\ai-agent\ai-interface\prompts\system
2025-09-22 15:51:46 - app - INFO - __init__.py:23 - 로깅 설정 완료
2025-09-22 15:51:46 - app - INFO - __init__.py:24 - 로그 디렉토리: C:\workspace\side\ai-agent\ai-interface\app\data\logs
2025-09-22 15:51:46 - app.infra.docker.client - WARNING - client.py:34 - Docker 초기화 실패: Error while fetching server API version: (2, 'CreateFile', '지정된 파일을 찾을 수 없습니다.')
2025-09-22 15:51:46 - app.infra.ai.prompt.prompt_manager - INFO - prompt_manager.py:47 - Loaded 2 system prompts from C:\workspace\side\ai-agent\ai-interface\prompts\system
2025-09-22 16:08:13 - app - INFO - __init__.py:23 - 로깅 설정 완료
2025-09-22 16:08:13 - app - INFO - __init__.py:24 - 로그 디렉토리: C:\workspace\side\ai-agent\ai-interface\app\data\logs
2025-09-22 16:08:13 - app.infra.docker.client - WARNING - client.py:34 - Docker 초기화 실패: Error while fetching server API version: (2, 'CreateFile', '지정된 파일을 찾을 수 없습니다.')
2025-09-22 16:08:13 - app.infra.ai.prompt.prompt_manager - INFO - prompt_manager.py:47 - Loaded 2 system prompts from C:\workspace\side\ai-agent\ai-interface\prompts\system
2025-09-22 16:13:16 - app - INFO - __init__.py:23 - 로깅 설정 완료
2025-09-22 16:13:16 - app - INFO - __init__.py:24 - 로그 디렉토리: C:\workspace\side\ai-agent\ai-interface\app\data\logs
2025-09-22 16:13:16 - app.infra.docker.client - WARNING - client.py:34 - Docker 초기화 실패: Error while fetching server API version: (2, 'CreateFile', '지정된 파일을 찾을 수 없습니다.')
2025-09-22 16:13:16 - app.infra.ai.prompt.prompt_manager - INFO - prompt_manager.py:47 - Loaded 2 system prompts from C:\workspace\side\ai-agent\ai-interface\prompts\system
2025-09-22 16:23:19 - app - INFO - __init__.py:23 - 로깅 설정 완료
2025-09-22 16:23:19 - app - INFO - __init__.py:24 - 로그 디렉토리: C:\workspace\side\ai-agent\ai-interface\app\data\logs
2025-09-22 16:23:19 - app.infra.docker.client - WARNING - client.py:34 - Docker 초기화 실패: Error while fetching server API version: (2, 'CreateFile', '지정된 파일을 찾을 수 없습니다.')
2025-09-22 16:23:19 - app.infra.ai.prompt.prompt_manager - INFO - prompt_manager.py:47 - Loaded 2 system prompts from C:\workspace\side\ai-agent\ai-interface\prompts\system
2025-09-22 16:24:45 - app - INFO - __init__.py:23 - 로깅 설정 완료
2025-09-22 16:24:45 - app - INFO - __init__.py:24 - 로그 디렉토리: C:\workspace\side\ai-agent\ai-interface\app\data\logs
2025-09-22 16:24:45 - app.infra.docker.client - WARNING - client.py:34 - Docker 초기화 실패: Error while fetching server API version: (2, 'CreateFile', '지정된 파일을 찾을 수 없습니다.')
2025-09-22 16:24:45 - app.infra.ai.prompt.prompt_manager - INFO - prompt_manager.py:47 - Loaded 2 system prompts from C:\workspace\side\ai-agent\ai-interface\prompts\system
2025-09-22 16:29:47 - app - INFO - __init__.py:23 - 로깅 설정 완료
2025-09-22 16:29:47 - app - INFO - __init__.py:24 - 로그 디렉토리: C:\workspace\side\ai-agent\ai-interface\app\data\logs
2025-09-22 16:29:47 - app.infra.docker.client - WARNING - client.py:34 - Docker 초기화 실패: Error while fetching server API version: (2, 'CreateFile', '지정된 파일을 찾을 수 없습니다.')
2025-09-22 16:29:47 - app.infra.ai.prompt.prompt_manager - INFO - prompt_manager.py:47 - Loaded 2 system prompts from C:\workspace\side\ai-agent\ai-interface\prompts\system
2025-09-22 16:57:37 - app - INFO - __init__.py:23 - 로깅 설정 완료
2025-09-22 16:57:37 - app - INFO - __init__.py:24 - 로그 디렉토리: C:\workspace\side\ai-agent\ai-interface\app\data\logs
2025-09-22 16:57:37 - app.infra.docker.client - WARNING - client.py:34 - Docker 초기화 실패: Error while fetching server API version: (2, 'CreateFile', '지정된 파일을 찾을 수 없습니다.')
2025-09-22 16:57:37 - app.infra.ai.prompt.prompt_manager - INFO - prompt_manager.py:47 - Loaded 2 system prompts from C:\workspace\side\ai-agent\ai-interface\prompts\system
2025-09-22 17:00:30 - app - INFO - __init__.py:23 - 로깅 설정 완료
2025-09-22 17:00:30 - app - INFO - __init__.py:24 - 로그 디렉토리: C:\workspace\side\ai-agent\ai-interface\app\data\logs
2025-09-22 17:00:30 - app.infra.docker.client - WARNING - client.py:34 - Docker 초기화 실패: Error while fetching server API version: (2, 'CreateFile', '지정된 파일을 찾을 수 없습니다.')
2025-09-22 17:00:30 - app.infra.ai.prompt.prompt_manager - INFO - prompt_manager.py:47 - Loaded 2 system prompts from C:\workspace\side\ai-agent\ai-interface\prompts\system
2025-09-22 17:07:16 - app - INFO - __init__.py:23 - 로깅 설정 완료
2025-09-22 17:07:16 - app - INFO - __init__.py:24 - 로그 디렉토리: C:\workspace\side\ai-agent\ai-interface\app\data\logs
2025-09-22 17:07:16 - app.infra.docker.client - WARNING - client.py:34 - Docker 초기화 실패: Error while fetching server API version: (2, 'CreateFile', '지정된 파일을 찾을 수 없습니다.')
2025-09-22 17:07:16 - app.infra.ai.prompt.prompt_manager - INFO - prompt_manager.py:47 - Loaded 2 system prompts from C:\workspace\side\ai-agent\ai-interface\prompts\system
2025-09-22 17:08:57 - app - INFO - __init__.py:23 - 로깅 설정 완료
2025-09-22 17:08:57 - app - INFO - __init__.py:24 - 로그 디렉토리: C:\workspace\side\ai-agent\ai-interface\app\data\logs
2025-09-22 17:08:57 - app.infra.docker.client - WARNING - client.py:34 - Docker 초기화 실패: Error while fetching server API version: (2, 'CreateFile', '지정된 파일을 찾을 수 없습니다.')
2025-09-22 17:08:57 - app.infra.ai.prompt.prompt_manager - INFO - prompt_manager.py:47 - Loaded 2 system prompts from C:\workspace\side\ai-agent\ai-interface\prompts\system
2025-09-22 17:13:57 - app - INFO - __init__.py:23 - 로깅 설정 완료
2025-09-22 17:13:57 - app - INFO - __init__.py:24 - 로그 디렉토리: C:\workspace\side\ai-agent\ai-interface\app\data\logs
2025-09-22 17:13:57 - app.infra.docker.client - WARNING - client.py:34 - Docker 초기화 실패: Error while fetching server API version: (2, 'CreateFile', '지정된 파일을 찾을 수 없습니다.')
2025-09-22 17:13:57 - app.infra.ai.prompt.prompt_manager - INFO - prompt_manager.py:47 - Loaded 2 system prompts from C:\workspace\side\ai-agent\ai-interface\prompts\system
2025-09-22 17:18:56 - app - INFO - __init__.py:23 - 로깅 설정 완료
2025-09-22 17:18:56 - app - INFO - __init__.py:24 - 로그 디렉토리: C:\workspace\side\ai-agent\ai-interface\app\data\logs
2025-09-22 17:18:56 - app.infra.docker.client - WARNING - client.py:34 - Docker 초기화 실패: Error while fetching server API version: (2, 'CreateFile', '지정된 파일을 찾을 수 없습니다.')
2025-09-22 17:18:56 - app.infra.ai.prompt.prompt_manager - INFO - prompt_manager.py:47 - Loaded 2 system prompts from C:\workspace\side\ai-agent\ai-interface\prompts\system
2025-09-22 17:23:57 - app - INFO - __init__.py:23 - 로깅 설정 완료
2025-09-22 17:23:57 - app - INFO - __init__.py:24 - 로그 디렉토리: C:\workspace\side\ai-agent\ai-interface\app\data\logs
2025-09-22 17:23:57 - app.infra.docker.client - WARNING - client.py:34 - Docker 초기화 실패: Error while fetching server API version: (2, 'CreateFile', '지정된 파일을 찾을 수 없습니다.')
2025-09-22 17:23:57 - app.infra.ai.prompt.prompt_manager - INFO - prompt_manager.py:47 - Loaded 2 system prompts from C:\workspace\side\ai-agent\ai-interface\prompts\system
2025-09-22 17:29:08 - app - INFO - __init__.py:23 - 로깅 설정 완료
2025-09-22 17:29:08 - app - INFO - __init__.py:24 - 로그 디렉토리: C:\workspace\side\ai-agent\ai-interface\app\data\logs
2025-09-22 17:29:08 - app.infra.docker.client - WARNING - client.py:34 - Docker 초기화 실패: Error while fetching server API version: (2, 'CreateFile', '지정된 파일을 찾을 수 없습니다.')
2025-09-22 17:29:08 - app.infra.ai.prompt.prompt_manager - INFO - prompt_manager.py:47 - Loaded 2 system prompts from C:\workspace\side\ai-agent\ai-interface\prompts\system
2025-09-23 09:23:26 - app - INFO - __init__.py:23 - 로깅 설정 완료
2025-09-23 09:23:26 - app - INFO - __init__.py:24 - 로그 디렉토리: C:\workspace\side\ai-agent\ai-interface\app\data\logs
2025-09-23 09:23:26 - app.infra.docker.client - WARNING - client.py:34 - Docker 초기화 실패: Error while fetching server API version: (2, 'CreateFile', '지정된 파일을 찾을 수 없습니다.')
2025-09-23 09:23:26 - app.infra.ai.prompt.prompt_manager - INFO - prompt_manager.py:47 - Loaded 3 system prompts from C:\workspace\side\ai-agent\ai-interface\prompts\system
2025-09-23 09:24:36 - app.domains.file.service - INFO - service.py:46 - 파일 처리 시작: 탄소중립과 기후 대응.txt, 크기: 285 bytes, 해시: f60f08f2036aa1bb...
2025-09-23 09:24:36 - app.domains.file.service - INFO - service.py:65 - 파일 처리 완료: 탄소중립과 기후 대응.txt
2025-09-23 09:38:35 - app - INFO - __init__.py:23 - 로깅 설정 완료
2025-09-23 09:38:35 - app - INFO - __init__.py:24 - 로그 디렉토리: C:\workspace\side\ai-agent\ai-interface\app\data\logs
2025-09-23 09:38:35 - app.infra.docker.client - WARNING - client.py:34 - Docker 초기화 실패: Error while fetching server API version: (2, 'CreateFile', '지정된 파일을 찾을 수 없습니다.')
2025-09-23 09:38:35 - app.infra.ai.prompt.prompt_manager - INFO - prompt_manager.py:47 - Loaded 3 system prompts from C:\workspace\side\ai-agent\ai-interface\prompts\system
2025-09-23 09:40:06 - app - INFO - __init__.py:23 - 로깅 설정 완료
2025-09-23 09:40:06 - app - INFO - __init__.py:24 - 로그 디렉토리: C:\workspace\side\ai-agent\ai-interface\app\data\logs
2025-09-23 09:40:06 - app.infra.docker.client - WARNING - client.py:34 - Docker 초기화 실패: Error while fetching server API version: (2, 'CreateFile', '지정된 파일을 찾을 수 없습니다.')
2025-09-23 09:40:06 - app.infra.ai.prompt.prompt_manager - INFO - prompt_manager.py:47 - Loaded 3 system prompts from C:\workspace\side\ai-agent\ai-interface\prompts\system
2025-09-23 09:40:22 - app - INFO - __init__.py:23 - 로깅 설정 완료
2025-09-23 09:40:22 - app - INFO - __init__.py:24 - 로그 디렉토리: C:\workspace\side\ai-agent\ai-interface\app\data\logs
2025-09-23 09:40:22 - app.infra.docker.client - WARNING - client.py:34 - Docker 초기화 실패: Error while fetching server API version: (2, 'CreateFile', '지정된 파일을 찾을 수 없습니다.')
2025-09-23 09:40:22 - app.infra.ai.prompt.prompt_manager - INFO - prompt_manager.py:47 - Loaded 3 system prompts from C:\workspace\side\ai-agent\ai-interface\prompts\system
2025-09-23 09:42:18 - app - INFO - __init__.py:23 - 로깅 설정 완료
2025-09-23 09:42:18 - app - INFO - __init__.py:24 - 로그 디렉토리: C:\workspace\side\ai-agent\ai-interface\app\data\logs
2025-09-23 09:42:19 - app.infra.docker.client - WARNING - client.py:34 - Docker 초기화 실패: Error while fetching server API version: (2, 'CreateFile', '지정된 파일을 찾을 수 없습니다.')
2025-09-23 09:42:19 - app.infra.ai.prompt.prompt_manager - INFO - prompt_manager.py:47 - Loaded 3 system prompts from C:\workspace\side\ai-agent\ai-interface\prompts\system
2025-09-23 09:43:29 - app - INFO - __init__.py:23 - 로깅 설정 완료
2025-09-23 09:43:29 - app - INFO - __init__.py:24 - 로그 디렉토리: C:\workspace\side\ai-agent\ai-interface\app\data\logs
2025-09-23 09:43:29 - app.infra.docker.client - WARNING - client.py:34 - Docker 초기화 실패: Error while fetching server API version: (2, 'CreateFile', '지정된 파일을 찾을 수 없습니다.')
2025-09-23 09:43:29 - app.infra.ai.prompt.prompt_manager - INFO - prompt_manager.py:47 - Loaded 3 system prompts from C:\workspace\side\ai-agent\ai-interface\prompts\system
2025-09-23 09:43:46 - app.domains.code.service - ERROR - service.py:41 - 코드 생성 실패: 코드 생성 실패: 'NoneType' object has no attribute 'ainvoke'
2025-09-23 09:43:46 - app.api.v1.endpoints.code - ERROR - code.py:33 - 코드 생성 실패: 코드 생성 실패: 'NoneType' object has no attribute 'ainvoke'
2025-09-23 09:43:52 - app.domains.code.service - ERROR - service.py:41 - 코드 생성 실패: 코드 생성 실패: 'NoneType' object has no attribute 'ainvoke'
2025-09-23 09:43:52 - app.api.v1.endpoints.code - ERROR - code.py:33 - 코드 생성 실패: 코드 생성 실패: 'NoneType' object has no attribute 'ainvoke'
2025-09-23 09:47:32 - app - INFO - __init__.py:23 - 로깅 설정 완료
2025-09-23 09:47:32 - app - INFO - __init__.py:24 - 로그 디렉토리: C:\workspace\side\ai-agent\ai-interface\app\data\logs
2025-09-23 09:47:32 - app.infra.docker.client - WARNING - client.py:34 - Docker 초기화 실패: Error while fetching server API version: (2, 'CreateFile', '지정된 파일을 찾을 수 없습니다.')
2025-09-23 09:47:32 - app.infra.ai.prompt.prompt_manager - INFO - prompt_manager.py:47 - Loaded 3 system prompts from C:\workspace\side\ai-agent\ai-interface\prompts\system
2025-09-23 09:48:02 - app - INFO - __init__.py:23 - 로깅 설정 완료
2025-09-23 09:48:02 - app - INFO - __init__.py:24 - 로그 디렉토리: C:\workspace\side\ai-agent\ai-interface\app\data\logs
2025-09-23 09:48:02 - app.infra.docker.client - WARNING - client.py:34 - Docker 초기화 실패: Error while fetching server API version: (2, 'CreateFile', '지정된 파일을 찾을 수 없습니다.')
2025-09-23 09:48:02 - app.infra.ai.prompt.prompt_manager - INFO - prompt_manager.py:47 - Loaded 3 system prompts from C:\workspace\side\ai-agent\ai-interface\prompts\system
2025-09-23 09:48:55 - app.domains.file.service - ERROR - service.py:72 - 파일 추출 오류: I/O operation on closed file.
2025-09-23 09:55:34 - app - INFO - __init__.py:23 - 로깅 설정 완료
2025-09-23 09:55:34 - app - INFO - __init__.py:24 - 로그 디렉토리: C:\workspace\side\ai-agent\ai-interface\app\data\logs
2025-09-23 09:55:34 - app.infra.docker.client - WARNING - client.py:34 - Docker 초기화 실패: Error while fetching server API version: (2, 'CreateFile', '지정된 파일을 찾을 수 없습니다.')
2025-09-23 09:55:34 - app.infra.ai.prompt.prompt_manager - INFO - prompt_manager.py:47 - Loaded 3 system prompts from C:\workspace\side\ai-agent\ai-interface\prompts\system
2025-09-23 09:55:58 - app - INFO - __init__.py:23 - 로깅 설정 완료
2025-09-23 09:55:58 - app - INFO - __init__.py:24 - 로그 디렉토리: C:\workspace\side\ai-agent\ai-interface\app\data\logs
2025-09-23 09:55:58 - app.infra.docker.client - WARNING - client.py:34 - Docker 초기화 실패: Error while fetching server API version: (2, 'CreateFile', '지정된 파일을 찾을 수 없습니다.')
2025-09-23 09:55:58 - app.infra.ai.prompt.prompt_manager - INFO - prompt_manager.py:47 - Loaded 3 system prompts from C:\workspace\side\ai-agent\ai-interface\prompts\system
2025-09-23 09:56:15 - app.domains.file.service - ERROR - service.py:87 - 파일 추출 오류: I/O operation on closed file.
2025-09-23 09:59:34 - app - INFO - __init__.py:23 - 로깅 설정 완료
2025-09-23 09:59:34 - app - INFO - __init__.py:24 - 로그 디렉토리: C:\workspace\side\ai-agent\ai-interface\app\data\logs
2025-09-23 09:59:34 - app.infra.docker.client - WARNING - client.py:34 - Docker 초기화 실패: Error while fetching server API version: (2, 'CreateFile', '지정된 파일을 찾을 수 없습니다.')
2025-09-23 09:59:34 - app.infra.ai.prompt.prompt_manager - INFO - prompt_manager.py:47 - Loaded 3 system prompts from C:\workspace\side\ai-agent\ai-interface\prompts\system
2025-09-23 09:59:53 - app - INFO - __init__.py:23 - 로깅 설정 완료
2025-09-23 09:59:53 - app - INFO - __init__.py:24 - 로그 디렉토리: C:\workspace\side\ai-agent\ai-interface\app\data\logs
2025-09-23 09:59:53 - app.infra.docker.client - WARNING - client.py:34 - Docker 초기화 실패: Error while fetching server API version: (2, 'CreateFile', '지정된 파일을 찾을 수 없습니다.')
2025-09-23 09:59:53 - app.infra.ai.prompt.prompt_manager - INFO - prompt_manager.py:47 - Loaded 3 system prompts from C:\workspace\side\ai-agent\ai-interface\prompts\system
2025-09-23 10:00:08 - app.domains.file.service - ERROR - service.py:87 - 파일 추출 오류: I/O operation on closed file.
2025-09-23 10:04:40 - app - INFO - __init__.py:23 - 로깅 설정 완료
2025-09-23 10:04:40 - app - INFO - __init__.py:24 - 로그 디렉토리: C:\workspace\side\ai-agent\ai-interface\app\data\logs
2025-09-23 10:04:40 - app.infra.docker.client - WARNING - client.py:34 - Docker 초기화 실패: Error while fetching server API version: (2, 'CreateFile', '지정된 파일을 찾을 수 없습니다.')
2025-09-23 10:04:40 - app.infra.ai.prompt.prompt_manager - INFO - prompt_manager.py:47 - Loaded 3 system prompts from C:\workspace\side\ai-agent\ai-interface\prompts\system
2025-09-23 10:04:53 - app.domains.file.service - ERROR - service.py:71 - 파일 추출 오류: I/O operation on closed file.
2025-09-23 10:06:02 - app - INFO - __init__.py:23 - 로깅 설정 완료
2025-09-23 10:06:02 - app - INFO - __init__.py:24 - 로그 디렉토리: C:\workspace\side\ai-agent\ai-interface\app\data\logs
2025-09-23 10:06:02 - app.infra.docker.client - WARNING - client.py:34 - Docker 초기화 실패: Error while fetching server API version: (2, 'CreateFile', '지정된 파일을 찾을 수 없습니다.')
2025-09-23 10:06:02 - app.infra.ai.prompt.prompt_manager - INFO - prompt_manager.py:47 - Loaded 3 system prompts from C:\workspace\side\ai-agent\ai-interface\prompts\system
2025-09-23 10:06:08 - app.domains.file.service - ERROR - service.py:71 - 파일 추출 오류: I/O operation on closed file.
2025-09-23 10:07:14 - app - INFO - __init__.py:23 - 로깅 설정 완료
2025-09-23 10:07:14 - app - INFO - __init__.py:24 - 로그 디렉토리: C:\workspace\side\ai-agent\ai-interface\app\data\logs
2025-09-23 10:07:14 - app.infra.docker.client - WARNING - client.py:34 - Docker 초기화 실패: Error while fetching server API version: (2, 'CreateFile', '지정된 파일을 찾을 수 없습니다.')
2025-09-23 10:07:14 - app.infra.ai.prompt.prompt_manager - INFO - prompt_manager.py:47 - Loaded 3 system prompts from C:\workspace\side\ai-agent\ai-interface\prompts\system
2025-09-23 10:07:24 - app.domains.file.service - ERROR - service.py:71 - 파일 추출 오류: I/O operation on closed file.
2025-09-23 10:12:16 - app - INFO - __init__.py:23 - 로깅 설정 완료
2025-09-23 10:12:16 - app - INFO - __init__.py:24 - 로그 디렉토리: C:\workspace\side\ai-agent\ai-interface\app\data\logs
2025-09-23 10:12:16 - app.infra.docker.client - WARNING - client.py:34 - Docker 초기화 실패: Error while fetching server API version: (2, 'CreateFile', '지정된 파일을 찾을 수 없습니다.')
2025-09-23 10:12:16 - app.infra.ai.prompt.prompt_manager - INFO - prompt_manager.py:47 - Loaded 3 system prompts from C:\workspace\side\ai-agent\ai-interface\prompts\system
2025-09-23 10:12:40 - app - INFO - __init__.py:23 - 로깅 설정 완료
2025-09-23 10:12:40 - app - INFO - __init__.py:24 - 로그 디렉토리: C:\workspace\side\ai-agent\ai-interface\app\data\logs
2025-09-23 10:12:40 - app.infra.docker.client - WARNING - client.py:34 - Docker 초기화 실패: Error while fetching server API version: (2, 'CreateFile', '지정된 파일을 찾을 수 없습니다.')
2025-09-23 10:12:40 - app.infra.ai.prompt.prompt_manager - INFO - prompt_manager.py:47 - Loaded 3 system prompts from C:\workspace\side\ai-agent\ai-interface\prompts\system
2025-09-23 10:13:02 - app.domains.file.service - INFO - service.py:45 - 파일 처리 시작: 탄소중립과 기후 대응.txt, 크기: 285 bytes, 해시: f60f08f2036aa1bb...
2025-09-23 10:13:02 - app.domains.file.service - INFO - service.py:64 - 파일 처리 완료: 탄소중립과 기후 대응.txt
2025-09-23 10:16:17 - app - INFO - __init__.py:23 - 로깅 설정 완료
2025-09-23 10:16:17 - app - INFO - __init__.py:24 - 로그 디렉토리: C:\workspace\side\ai-agent\ai-interface\app\data\logs
2025-09-23 10:16:17 - app.infra.docker.client - WARNING - client.py:34 - Docker 초기화 실패: Error while fetching server API version: (2, 'CreateFile', '지정된 파일을 찾을 수 없습니다.')
2025-09-23 10:16:17 - app.infra.ai.prompt.prompt_manager - INFO - prompt_manager.py:47 - Loaded 3 system prompts from C:\workspace\side\ai-agent\ai-interface\prompts\system
2025-09-23 10:16:37 - app.domains.file.service - INFO - service.py:45 - 파일 처리 시작: 탄소중립과 기후 대응.txt, 크기: 285 bytes, 해시: f60f08f2036aa1bb...
2025-09-23 10:16:37 - app.domains.file.service - INFO - service.py:64 - 파일 처리 완료: 탄소중립과 기후 대응.txt
2025-09-23 10:17:28 - app.domains.file.service - INFO - service.py:45 - 파일 처리 시작: TB_SHC_FRNC_INFO_202507.csv, 크기: 241492 bytes, 해시: 1e45cd46f80c0c7d...
2025-09-23 10:17:28 - app.domains.file.service - ERROR - service.py:71 - 파일 추출 오류: Excel 추출 실패: Excel file format cannot be determined, you must specify an engine manually.
2025-09-23 10:17:48 - app.domains.file.service - INFO - service.py:45 - 파일 처리 시작: 22~25년_공공배달앱인_대구로_생활_플랫폼_내_결제정보.xlsx, 크기: 10835 bytes, 해시: 66e69af878c365a2...
2025-09-23 10:17:48 - app.domains.file.service - INFO - service.py:64 - 파일 처리 완료: 22~25년_공공배달앱인_대구로_생활_플랫폼_내_결제정보.xlsx
2025-09-23 10:20:35 - app.domains.file.service - INFO - service.py:45 - 파일 처리 시작: 일자별_대출_조회_현황_통계정보.xlsx, 크기: 10554 bytes, 해시: 0cc9e746feb4d5e9...
2025-09-23 10:20:35 - app.domains.file.service - INFO - service.py:64 - 파일 처리 완료: 일자별_대출_조회_현황_통계정보.xlsx
2025-09-23 10:21:44 - app.domains.file.service - INFO - service.py:45 - 파일 처리 시작: 일자별_대출_조회_현황_통계정보.xlsx, 크기: 10554 bytes, 해시: 0cc9e746feb4d5e9...
2025-09-23 10:21:44 - app.domains.file.service - INFO - service.py:64 - 파일 처리 완료: 일자별_대출_조회_현황_통계정보.xlsx
2025-09-23 10:23:31 - app.domains.code.service - ERROR - service.py:41 - 코드 생성 실패: 코드 생성 실패: 'NoneType' object has no attribute 'ainvoke'
2025-09-23 10:23:31 - app.api.v1.endpoints.code - ERROR - code.py:22 - 코드 생성 실패: 코드 생성 실패: 'NoneType' object has no attribute 'ainvoke'
2025-09-23 10:23:34 - app.domains.code.service - ERROR - service.py:41 - 코드 생성 실패: 코드 생성 실패: 'NoneType' object has no attribute 'ainvoke'
2025-09-23 10:23:34 - app.api.v1.endpoints.code - ERROR - code.py:22 - 코드 생성 실패: 코드 생성 실패: 'NoneType' object has no attribute 'ainvoke'
2025-09-23 10:23:55 - app.domains.code.service - ERROR - service.py:41 - 코드 생성 실패: 코드 생성 실패: 'NoneType' object has no attribute 'ainvoke'
2025-09-23 10:23:55 - app.api.v1.endpoints.code - ERROR - code.py:22 - 코드 생성 실패: 코드 생성 실패: 'NoneType' object has no attribute 'ainvoke'
2025-09-23 10:26:25 - app.domains.file.service - INFO - service.py:45 - 파일 처리 시작: 일자별_대출_조회_현황_통계정보.xlsx, 크기: 10554 bytes, 해시: 0cc9e746feb4d5e9...
2025-09-23 10:26:25 - app.domains.file.service - INFO - service.py:64 - 파일 처리 완료: 일자별_대출_조회_현황_통계정보.xlsx
2025-09-23 10:28:16 - app.domains.file.service - INFO - service.py:45 - 파일 처리 시작: 지역화폐_BC카드_소비_결합_데이터.xlsx, 크기: 12793 bytes, 해시: 41c5090427d8511b...
2025-09-23 10:28:16 - app.domains.file.service - INFO - service.py:64 - 파일 처리 완료: 지역화폐_BC카드_소비_결합_데이터.xlsx
2025-09-23 10:28:21 - app - INFO - __init__.py:23 - 로깅 설정 완료
2025-09-23 10:28:21 - app - INFO - __init__.py:24 - 로그 디렉토리: C:\workspace\side\ai-agent\ai-interface\app\data\logs
2025-09-23 10:28:21 - app.infra.docker.client - INFO - client.py:32 - Docker 클라이언트 초기화 완료
2025-09-23 10:28:21 - app.infra.ai.prompt.prompt_manager - INFO - prompt_manager.py:47 - Loaded 3 system prompts from C:\workspace\side\ai-agent\ai-interface\prompts\system
2025-09-23 10:28:33 - app.domains.file.service - INFO - service.py:45 - 파일 처리 시작: 수도권의_대중교통(버스지하철등)_대한_승_하차_이용내역_데이터.xlsx, 크기: 11031 bytes, 해시: 7cc4cbb400bdffb7...
2025-09-23 10:28:34 - app.domains.file.service - INFO - service.py:64 - 파일 처리 완료: 수도권의_대중교통(버스지하철등)_대한_승_하차_이용내역_데이터.xlsx
2025-09-23 10:28:44 - app - INFO - __init__.py:23 - 로깅 설정 완료
2025-09-23 10:28:44 - app - INFO - __init__.py:24 - 로그 디렉토리: C:\workspace\side\ai-agent\ai-interface\app\data\logs
2025-09-23 10:28:44 - app.infra.docker.client - INFO - client.py:32 - Docker 클라이언트 초기화 완료
2025-09-23 10:28:44 - app.infra.ai.prompt.prompt_manager - INFO - prompt_manager.py:47 - Loaded 4 system prompts from C:\workspace\side\ai-agent\ai-interface\prompts\system
2025-09-23 10:28:54 - app.domains.file.service - INFO - service.py:45 - 파일 처리 시작: 일자별_대출_조회_현황_통계정보.xlsx, 크기: 10554 bytes, 해시: 0cc9e746feb4d5e9...
2025-09-23 10:28:54 - app.domains.file.service - INFO - service.py:64 - 파일 처리 완료: 일자별_대출_조회_현황_통계정보.xlsx
2025-09-23 10:33:44 - app - INFO - __init__.py:23 - 로깅 설정 완료
2025-09-23 10:33:44 - app - INFO - __init__.py:24 - 로그 디렉토리: C:\workspace\side\ai-agent\ai-interface\app\data\logs
2025-09-23 10:33:44 - app.infra.docker.client - INFO - client.py:32 - Docker 클라이언트 초기화 완료
2025-09-23 10:33:44 - app.infra.ai.prompt.prompt_manager - INFO - prompt_manager.py:47 - Loaded 5 system prompts from C:\workspace\side\ai-agent\ai-interface\prompts\system
2025-09-23 10:37:29 - app - INFO - __init__.py:23 - 로깅 설정 완료
2025-09-23 10:37:29 - app - INFO - __init__.py:24 - 로그 디렉토리: C:\workspace\side\ai-agent\ai-interface\app\data\logs
2025-09-23 10:37:29 - app.infra.docker.client - INFO - client.py:32 - Docker 클라이언트 초기화 완료
2025-09-23 10:37:29 - app.infra.ai.prompt.prompt_manager - INFO - prompt_manager.py:47 - Loaded 5 system prompts from C:\workspace\side\ai-agent\ai-interface\prompts\system
2025-09-23 10:39:22 - app - INFO - __init__.py:23 - 로깅 설정 완료
2025-09-23 10:39:22 - app - INFO - __init__.py:24 - 로그 디렉토리: C:\workspace\side\ai-agent\ai-interface\app\data\logs
2025-09-23 10:39:22 - app.infra.docker.client - INFO - client.py:32 - Docker 클라이언트 초기화 완료
2025-09-23 10:39:22 - app.infra.ai.prompt.prompt_manager - INFO - prompt_manager.py:47 - Loaded 5 system prompts from C:\workspace\side\ai-agent\ai-interface\prompts\system
2025-09-23 10:40:05 - app.infra.ai.code.code_generator - ERROR - code_generator.py:119 - 코드 생성 실패: 'LLMMetadata' object has no attribute 'model_name'
2025-09-23 10:40:05 - app.domains.code.service - ERROR - service.py:42 - 코드 생성 실패: 코드 생성 실패: 'LLMMetadata' object has no attribute 'model_name'
2025-09-23 10:40:05 - app.api.v1.endpoints.code - ERROR - code.py:22 - 코드 생성 실패: 코드 생성 실패: 'LLMMetadata' object has no attribute 'model_name'
2025-09-23 10:45:00 - app - INFO - __init__.py:23 - 로깅 설정 완료
2025-09-23 10:45:00 - app - INFO - __init__.py:24 - 로그 디렉토리: C:\workspace\side\ai-agent\ai-interface\app\data\logs
2025-09-23 10:45:01 - app.infra.docker.client - INFO - client.py:32 - Docker 클라이언트 초기화 완료
2025-09-23 10:45:01 - app.infra.ai.prompt.prompt_manager - INFO - prompt_manager.py:47 - Loaded 5 system prompts from C:\workspace\side\ai-agent\ai-interface\prompts\system
2025-09-23 10:45:36 - app.infra.docker.client - INFO - client.py:45 - 이미지 존재 확인: jupyter/scipy-notebook:latest
2025-09-23 10:45:40 - app.domains.code.service - ERROR - service.py:65 - 코드 실행 실패: 1 validation error for CodeExecutionResponse
language
  Field required [type=missing, input_value={'execution_id': '2a493d6...nment.DOCKER: 'docker'>}, input_type=dict]
    For further information visit https://errors.pydantic.dev/2.11/v/missing
2025-09-23 10:47:26 - app.infra.docker.client - INFO - client.py:45 - 이미지 존재 확인: jupyter/scipy-notebook:latest
2025-09-23 10:47:28 - app.domains.code.service - ERROR - service.py:65 - 코드 실행 실패: 1 validation error for CodeExecutionResponse
language
  Field required [type=missing, input_value={'execution_id': '7210879...nment.DOCKER: 'docker'>}, input_type=dict]
    For further information visit https://errors.pydantic.dev/2.11/v/missing
2025-09-23 10:47:42 - app - INFO - __init__.py:23 - 로깅 설정 완료
2025-09-23 10:47:42 - app - INFO - __init__.py:24 - 로그 디렉토리: C:\workspace\side\ai-agent\ai-interface\app\data\logs
2025-09-23 10:47:42 - app.infra.docker.client - INFO - client.py:32 - Docker 클라이언트 초기화 완료
2025-09-23 10:47:42 - app.infra.ai.prompt.prompt_manager - INFO - prompt_manager.py:47 - Loaded 5 system prompts from C:\workspace\side\ai-agent\ai-interface\prompts\system
2025-09-23 10:48:04 - app.infra.docker.client - INFO - client.py:45 - 이미지 존재 확인: jupyter/scipy-notebook:latest
2025-09-23 10:48:07 - app.domains.code.service - ERROR - service.py:65 - 코드 실행 실패: 1 validation error for CodeExecutionResponse
language
  Field required [type=missing, input_value={'execution_id': '1835eac...nment.DOCKER: 'docker'>}, input_type=dict]
    For further information visit https://errors.pydantic.dev/2.11/v/missing
2025-09-23 10:50:43 - app - INFO - __init__.py:23 - 로깅 설정 완료
2025-09-23 10:50:43 - app - INFO - __init__.py:24 - 로그 디렉토리: C:\workspace\side\ai-agent\ai-interface\app\data\logs
2025-09-23 10:50:43 - app.infra.docker.client - INFO - client.py:32 - Docker 클라이언트 초기화 완료
2025-09-23 10:50:43 - app.infra.ai.prompt.prompt_manager - INFO - prompt_manager.py:47 - Loaded 5 system prompts from C:\workspace\side\ai-agent\ai-interface\prompts\system
2025-09-23 10:51:30 - app.infra.docker.client - INFO - client.py:45 - 이미지 존재 확인: jupyter/scipy-notebook:latest
2025-09-23 10:51:58 - app.infra.docker.client - INFO - client.py:45 - 이미지 존재 확인: jupyter/scipy-notebook:latest
2025-09-23 10:53:21 - app.infra.docker.client - INFO - client.py:45 - 이미지 존재 확인: jupyter/scipy-notebook:latest
2025-09-23 10:57:39 - app - INFO - __init__.py:23 - 로깅 설정 완료
2025-09-23 10:57:39 - app - INFO - __init__.py:24 - 로그 디렉토리: C:\workspace\side\ai-agent\ai-interface\app\data\logs
2025-09-23 10:57:39 - app.infra.docker.client - INFO - client.py:32 - Docker 클라이언트 초기화 완료
2025-09-23 10:57:39 - app.infra.ai.prompt.prompt_manager - INFO - prompt_manager.py:47 - Loaded 5 system prompts from C:\workspace\side\ai-agent\ai-interface\prompts\system
2025-09-23 10:58:31 - app.infra.docker.client - INFO - client.py:45 - 이미지 존재 확인: jupyter/scipy-notebook:latest
2025-09-23 11:00:52 - app.infra.docker.client - INFO - client.py:45 - 이미지 존재 확인: jupyter/scipy-notebook:latest
2025-09-23 11:10:05 - app - INFO - __init__.py:23 - 로깅 설정 완료
2025-09-23 11:10:05 - app - INFO - __init__.py:24 - 로그 디렉토리: C:\workspace\side\ai-agent\ai-interface\app\data\logs
2025-09-23 11:10:05 - app.infra.docker.client - INFO - client.py:32 - Docker 클라이언트 초기화 완료
2025-09-23 11:10:05 - app.infra.ai.prompt.prompt_manager - INFO - prompt_manager.py:47 - Loaded 5 system prompts from C:\workspace\side\ai-agent\ai-interface\prompts\system
2025-09-23 11:10:37 - app.infra.docker.client - INFO - client.py:45 - 이미지 존재 확인: jupyter/scipy-notebook:latest
2025-09-23 11:11:33 - app.infra.docker.client - INFO - client.py:45 - 이미지 존재 확인: jupyter/scipy-notebook:latest
2025-09-23 11:13:31 - app.infra.docker.client - INFO - client.py:45 - 이미지 존재 확인: jupyter/scipy-notebook:latest
2025-09-23 13:11:29 - app.domains.file.service - INFO - service.py:45 - 파일 처리 시작: 일자별_대출_조회_현황_통계정보.xlsx, 크기: 10554 bytes, 해시: 0cc9e746feb4d5e9...
2025-09-23 13:11:30 - app.domains.file.service - INFO - service.py:64 - 파일 처리 완료: 일자별_대출_조회_현황_통계정보.xlsx
2025-09-23 13:18:47 - app - INFO - __init__.py:23 - 로깅 설정 완료
2025-09-23 13:18:47 - app - INFO - __init__.py:24 - 로그 디렉토리: C:\workspace\side\ai-agent\ai-interface\app\data\logs
2025-09-23 13:18:47 - app.infra.docker.client - INFO - client.py:32 - Docker 클라이언트 초기화 완료
2025-09-23 13:18:47 - app.infra.ai.prompt.prompt_manager - INFO - prompt_manager.py:47 - Loaded 5 system prompts from C:\workspace\side\ai-agent\ai-interface\prompts\system
2025-09-23 13:22:24 - app - INFO - __init__.py:23 - 로깅 설정 완료
2025-09-23 13:22:24 - app - INFO - __init__.py:24 - 로그 디렉토리: C:\workspace\side\ai-agent\ai-interface\app\data\logs
2025-09-23 13:22:24 - app.infra.docker.client - INFO - client.py:32 - Docker 클라이언트 초기화 완료
2025-09-23 13:22:24 - app.infra.ai.prompt.prompt_manager - INFO - prompt_manager.py:47 - Loaded 5 system prompts from C:\workspace\side\ai-agent\ai-interface\prompts\system
2025-09-23 13:23:25 - app.domains.file.service - INFO - service.py:45 - 파일 처리 시작: 일자별_대출_조회_현황_통계정보.xlsx, 크기: 10554 bytes, 해시: 0cc9e746feb4d5e9...
2025-09-23 13:23:25 - app.domains.file.service - INFO - service.py:64 - 파일 처리 완료: 일자별_대출_조회_현황_통계정보.xlsx
2025-09-23 13:26:48 - app.infra.docker.client - INFO - client.py:45 - 이미지 존재 확인: jupyter/scipy-notebook:latest
2025-09-23 13:27:27 - app - INFO - __init__.py:23 - 로깅 설정 완료
2025-09-23 13:27:27 - app - INFO - __init__.py:24 - 로그 디렉토리: C:\workspace\side\ai-agent\ai-interface\app\data\logs
2025-09-23 13:27:27 - app.infra.docker.client - INFO - client.py:32 - Docker 클라이언트 초기화 완료
2025-09-23 13:27:27 - app.infra.ai.prompt.prompt_manager - INFO - prompt_manager.py:47 - Loaded 5 system prompts from C:\workspace\side\ai-agent\ai-interface\prompts\system
2025-09-23 13:27:56 - app.infra.docker.client - INFO - client.py:45 - 이미지 존재 확인: jupyter/scipy-notebook:latest
2025-09-23 13:30:04 - app.domains.file.service - INFO - service.py:45 - 파일 처리 시작: 지역화폐_BC카드_소비_결합_데이터.xlsx, 크기: 12793 bytes, 해시: 41c5090427d8511b...
2025-09-23 13:30:04 - app.domains.file.service - INFO - service.py:64 - 파일 처리 완료: 지역화폐_BC카드_소비_결합_데이터.xlsx
2025-09-23 13:30:07 - app - INFO - __init__.py:23 - 로깅 설정 완료
2025-09-23 13:30:07 - app - INFO - __init__.py:24 - 로그 디렉토리: C:\workspace\side\ai-agent\ai-interface\app\data\logs
2025-09-23 13:30:07 - app.infra.docker.client - INFO - client.py:32 - Docker 클라이언트 초기화 완료
2025-09-23 13:30:07 - app.infra.ai.prompt.prompt_manager - INFO - prompt_manager.py:47 - Loaded 5 system prompts from C:\workspace\side\ai-agent\ai-interface\prompts\system
2025-09-23 13:30:27 - app.domains.file.service - INFO - service.py:45 - 파일 처리 시작: 지역화폐_BC카드_소비_결합_데이터.xlsx, 크기: 12793 bytes, 해시: 41c5090427d8511b...
2025-09-23 13:30:28 - app.domains.file.service - INFO - service.py:64 - 파일 처리 완료: 지역화폐_BC카드_소비_결합_데이터.xlsx
2025-09-23 13:35:31 - app.domains.file.service - INFO - service.py:45 - 파일 처리 시작: 일자별_대출_조회_현황_통계정보.xlsx, 크기: 10554 bytes, 해시: 0cc9e746feb4d5e9...
2025-09-23 13:35:31 - app.domains.file.service - INFO - service.py:64 - 파일 처리 완료: 일자별_대출_조회_현황_통계정보.xlsx
2025-09-23 14:13:30 - app - INFO - __init__.py:23 - 로깅 설정 완료
2025-09-23 14:13:30 - app - INFO - __init__.py:24 - 로그 디렉토리: C:\workspace\side\ai-agent\ai-interface\app\data\logs
2025-09-23 14:13:30 - app.infra.docker.client - INFO - client.py:32 - Docker 클라이언트 초기화 완료
2025-09-23 14:13:30 - app.infra.ai.prompt.prompt_manager - INFO - prompt_manager.py:47 - Loaded 5 system prompts from C:\workspace\side\ai-agent\ai-interface\prompts\system
2025-09-23 14:18:30 - app - INFO - __init__.py:23 - 로깅 설정 완료
2025-09-23 14:18:30 - app - INFO - __init__.py:24 - 로그 디렉토리: C:\workspace\side\ai-agent\ai-interface\app\data\logs
2025-09-23 14:18:30 - app.infra.docker.client - INFO - client.py:32 - Docker 클라이언트 초기화 완료
2025-09-23 14:18:30 - app.infra.ai.prompt.prompt_manager - INFO - prompt_manager.py:47 - Loaded 5 system prompts from C:\workspace\side\ai-agent\ai-interface\prompts\system
2025-09-23 14:23:31 - app - INFO - __init__.py:23 - 로깅 설정 완료
2025-09-23 14:23:31 - app - INFO - __init__.py:24 - 로그 디렉토리: C:\workspace\side\ai-agent\ai-interface\app\data\logs
2025-09-23 14:23:32 - app.infra.docker.client - INFO - client.py:32 - Docker 클라이언트 초기화 완료
2025-09-23 14:23:32 - app.infra.ai.prompt.prompt_manager - INFO - prompt_manager.py:47 - Loaded 5 system prompts from C:\workspace\side\ai-agent\ai-interface\prompts\system
2025-09-23 14:28:32 - app - INFO - __init__.py:23 - 로깅 설정 완료
2025-09-23 14:28:32 - app - INFO - __init__.py:24 - 로그 디렉토리: C:\workspace\side\ai-agent\ai-interface\app\data\logs
2025-09-23 14:28:32 - app.infra.docker.client - INFO - client.py:32 - Docker 클라이언트 초기화 완료
2025-09-23 14:28:32 - app.infra.ai.prompt.prompt_manager - INFO - prompt_manager.py:47 - Loaded 5 system prompts from C:\workspace\side\ai-agent\ai-interface\prompts\system
2025-09-23 14:33:34 - app - INFO - __init__.py:23 - 로깅 설정 완료
2025-09-23 14:33:34 - app - INFO - __init__.py:24 - 로그 디렉토리: C:\workspace\side\ai-agent\ai-interface\app\data\logs
2025-09-23 14:33:34 - app.infra.docker.client - INFO - client.py:32 - Docker 클라이언트 초기화 완료
2025-09-23 14:33:34 - app.infra.ai.prompt.prompt_manager - INFO - prompt_manager.py:47 - Loaded 5 system prompts from C:\workspace\side\ai-agent\ai-interface\prompts\system
2025-09-23 14:36:22 - app - INFO - __init__.py:23 - 로깅 설정 완료
2025-09-23 14:36:22 - app - INFO - __init__.py:24 - 로그 디렉토리: C:\workspace\side\ai-agent\ai-interface\app\data\logs
2025-09-23 14:36:22 - app.infra.docker.client - INFO - client.py:32 - Docker 클라이언트 초기화 완료
2025-09-23 14:36:22 - app.infra.ai.prompt.prompt_manager - INFO - prompt_manager.py:47 - Loaded 5 system prompts from C:\workspace\side\ai-agent\ai-interface\prompts\system
2025-09-23 14:40:46 - app - INFO - __init__.py:23 - 로깅 설정 완료
2025-09-23 14:40:46 - app - INFO - __init__.py:24 - 로그 디렉토리: C:\workspace\side\ai-agent\ai-interface\app\data\logs
2025-09-23 14:40:46 - app.infra.docker.client - INFO - client.py:32 - Docker 클라이언트 초기화 완료
2025-09-23 14:40:46 - app.infra.ai.prompt.prompt_manager - INFO - prompt_manager.py:47 - Loaded 5 system prompts from C:\workspace\side\ai-agent\ai-interface\prompts\system
2025-09-23 14:41:41 - app.domains.file.service - INFO - service.py:45 - 파일 처리 시작: 일자별_대출_조회_현황_통계정보.xlsx, 크기: 10554 bytes, 해시: 0cc9e746feb4d5e9...
2025-09-23 14:41:42 - app.domains.file.service - INFO - service.py:64 - 파일 처리 완료: 일자별_대출_조회_현황_통계정보.xlsx
2025-09-23 14:41:55 - app.domains.code.service - ERROR - service.py:64 - 코드 생성 실패: 'Settings' object has no attribute 'default_model_name'
2025-09-23 14:42:14 - app.domains.file.service - INFO - service.py:45 - 파일 처리 시작: 일자별_대출_조회_현황_통계정보.xlsx, 크기: 10554 bytes, 해시: 0cc9e746feb4d5e9...
2025-09-23 14:42:14 - app.domains.file.service - INFO - service.py:64 - 파일 처리 완료: 일자별_대출_조회_현황_통계정보.xlsx
2025-09-23 14:42:20 - app.domains.code.service - ERROR - service.py:64 - 코드 생성 실패: 'Settings' object has no attribute 'default_model_name'
2025-09-23 14:42:26 - app.domains.file.service - INFO - service.py:45 - 파일 처리 시작: 일자별_대출_조회_현황_통계정보.xlsx, 크기: 10554 bytes, 해시: 0cc9e746feb4d5e9...
2025-09-23 14:42:27 - app.domains.file.service - INFO - service.py:64 - 파일 처리 완료: 일자별_대출_조회_현황_통계정보.xlsx
2025-09-23 14:42:36 - app.domains.code.service - ERROR - service.py:64 - 코드 생성 실패: 'Settings' object has no attribute 'default_model_name'
2025-09-23 14:43:37 - app - INFO - __init__.py:23 - 로깅 설정 완료
2025-09-23 14:43:37 - app - INFO - __init__.py:24 - 로그 디렉토리: C:\workspace\side\ai-agent\ai-interface\app\data\logs
2025-09-23 14:43:37 - app.infra.docker.client - INFO - client.py:32 - Docker 클라이언트 초기화 완료
2025-09-23 14:43:37 - app.infra.ai.prompt.prompt_manager - INFO - prompt_manager.py:47 - Loaded 5 system prompts from C:\workspace\side\ai-agent\ai-interface\prompts\system
2025-09-23 14:43:37 - app.domains.file.service - INFO - service.py:45 - 파일 처리 시작: 일자별_대출_조회_현황_통계정보.xlsx, 크기: 10554 bytes, 해시: 0cc9e746feb4d5e9...
2025-09-23 14:43:38 - app.domains.file.service - INFO - service.py:64 - 파일 처리 완료: 일자별_대출_조회_현황_통계정보.xlsx
2025-09-23 14:45:21 - app.infra.ai.llm.llm_manager - ERROR - llm_manager.py:63 - Failed to generate response: model 'llama3.1:8b' not found (status code: 404)
2025-09-23 14:45:21 - app.domains.llm.service - ERROR - service.py:85 - LLM 응답 생성 오류: Failed to generate response: model 'llama3.1:8b' not found (status code: 404)
2025-09-23 14:45:23 - app.domains.code.service - ERROR - service.py:61 - 코드 생성 실패: 500: 응답 생성 중 오류가 발생했습니다.
2025-09-23 14:49:12 - app - INFO - __init__.py:23 - 로깅 설정 완료
2025-09-23 14:49:12 - app - INFO - __init__.py:24 - 로그 디렉토리: C:\workspace\side\ai-agent\ai-interface\app\data\logs
2025-09-23 14:49:12 - app.infra.docker.client - INFO - client.py:32 - Docker 클라이언트 초기화 완료
2025-09-23 14:49:12 - app.infra.ai.prompt.prompt_manager - INFO - prompt_manager.py:47 - Loaded 5 system prompts from C:\workspace\side\ai-agent\ai-interface\prompts\system
2025-09-23 14:49:15 - app.domains.file.service - INFO - service.py:45 - 파일 처리 시작: 일자별_대출_조회_현황_통계정보.xlsx, 크기: 10554 bytes, 해시: 0cc9e746feb4d5e9...
2025-09-23 14:49:19 - app.domains.file.service - INFO - service.py:64 - 파일 처리 완료: 일자별_대출_조회_현황_통계정보.xlsx
2025-09-23 14:53:07 - app - INFO - __init__.py:23 - 로깅 설정 완료
2025-09-23 14:53:07 - app - INFO - __init__.py:24 - 로그 디렉토리: C:\workspace\side\ai-agent\ai-interface\app\data\logs
2025-09-23 14:53:07 - app.infra.docker.client - INFO - client.py:32 - Docker 클라이언트 초기화 완료
2025-09-23 14:53:07 - app.infra.ai.prompt.prompt_manager - INFO - prompt_manager.py:47 - Loaded 5 system prompts from C:\workspace\side\ai-agent\ai-interface\prompts\system
2025-09-23 14:53:16 - app.domains.file.service - INFO - service.py:45 - 파일 처리 시작: 일자별_대출_조회_현황_통계정보.xlsx, 크기: 10554 bytes, 해시: 0cc9e746feb4d5e9...
2025-09-23 14:53:16 - app.domains.file.service - INFO - service.py:64 - 파일 처리 완료: 일자별_대출_조회_현황_통계정보.xlsx
2025-09-23 14:54:50 - app - INFO - __init__.py:23 - 로깅 설정 완료
2025-09-23 14:54:50 - app - INFO - __init__.py:24 - 로그 디렉토리: C:\workspace\side\ai-agent\ai-interface\app\data\logs
2025-09-23 14:54:50 - app.infra.docker.client - INFO - client.py:32 - Docker 클라이언트 초기화 완료
2025-09-23 14:54:50 - app.infra.ai.prompt.prompt_manager - INFO - prompt_manager.py:47 - Loaded 5 system prompts from C:\workspace\side\ai-agent\ai-interface\prompts\system
2025-09-23 14:56:05 - app.infra.docker.client - INFO - client.py:45 - 이미지 존재 확인: jupyter/scipy-notebook:latest
2025-09-23 14:56:25 - app - INFO - __init__.py:23 - 로깅 설정 완료
2025-09-23 14:56:25 - app - INFO - __init__.py:24 - 로그 디렉토리: C:\workspace\side\ai-agent\ai-interface\app\data\logs
2025-09-23 14:56:25 - app.infra.docker.client - INFO - client.py:32 - Docker 클라이언트 초기화 완료
2025-09-23 14:56:25 - app.infra.ai.prompt.prompt_manager - INFO - prompt_manager.py:47 - Loaded 5 system prompts from C:\workspace\side\ai-agent\ai-interface\prompts\system
2025-09-23 14:56:34 - app.infra.docker.client - INFO - client.py:45 - 이미지 존재 확인: jupyter/scipy-notebook:latest
2025-09-23 14:56:47 - app.domains.file.service - INFO - service.py:45 - 파일 처리 시작: 일자별_대출_조회_현황_통계정보.xlsx, 크기: 10554 bytes, 해시: 0cc9e746feb4d5e9...
2025-09-23 14:56:47 - app.domains.file.service - INFO - service.py:64 - 파일 처리 완료: 일자별_대출_조회_현황_통계정보.xlsx
2025-09-23 14:58:02 - app - INFO - __init__.py:23 - 로깅 설정 완료
2025-09-23 14:58:02 - app - INFO - __init__.py:24 - 로그 디렉토리: C:\workspace\side\ai-agent\ai-interface\app\data\logs
2025-09-23 14:58:02 - app.infra.docker.client - INFO - client.py:32 - Docker 클라이언트 초기화 완료
2025-09-23 14:58:02 - app.infra.ai.prompt.prompt_manager - INFO - prompt_manager.py:47 - Loaded 5 system prompts from C:\workspace\side\ai-agent\ai-interface\prompts\system
2025-09-23 15:00:21 - app.domains.file.service - INFO - service.py:45 - 파일 처리 시작: 일자별_대출_조회_현황_통계정보.xlsx, 크기: 10554 bytes, 해시: 0cc9e746feb4d5e9...
2025-09-23 15:00:21 - app.domains.file.service - INFO - service.py:64 - 파일 처리 완료: 일자별_대출_조회_현황_통계정보.xlsx
2025-09-23 15:01:33 - app.infra.docker.client - INFO - client.py:45 - 이미지 존재 확인: jupyter/scipy-notebook:latest
2025-09-23 15:01:58 - app.infra.docker.client - INFO - client.py:45 - 이미지 존재 확인: jupyter/scipy-notebook:latest
2025-09-23 15:13:53 - app - INFO - __init__.py:23 - 로깅 설정 완료
2025-09-23 15:13:53 - app - INFO - __init__.py:24 - 로그 디렉토리: C:\workspace\side\ai-agent\ai-interface\app\data\logs
2025-09-23 15:13:53 - app.infra.docker.client - INFO - client.py:32 - Docker 클라이언트 초기화 완료
2025-09-23 15:13:53 - app.infra.ai.prompt.prompt_manager - INFO - prompt_manager.py:47 - Loaded 5 system prompts from C:\workspace\side\ai-agent\ai-interface\prompts\system
2025-09-23 15:30:20 - app - INFO - __init__.py:23 - 로깅 설정 완료
2025-09-23 15:30:20 - app - INFO - __init__.py:24 - 로그 디렉토리: C:\workspace\side\ai-agent\ai-interface\app\data\logs
2025-09-23 15:30:20 - app.infra.docker.client - INFO - client.py:32 - Docker 클라이언트 초기화 완료
2025-09-23 15:30:20 - app.infra.ai.prompt.prompt_manager - INFO - prompt_manager.py:47 - Loaded 5 system prompts from C:\workspace\side\ai-agent\ai-interface\prompts\system
2025-09-23 15:35:22 - app - INFO - __init__.py:23 - 로깅 설정 완료
2025-09-23 15:35:22 - app - INFO - __init__.py:24 - 로그 디렉토리: C:\workspace\side\ai-agent\ai-interface\app\data\logs
2025-09-23 15:35:22 - app.infra.docker.client - INFO - client.py:32 - Docker 클라이언트 초기화 완료
2025-09-23 15:35:22 - app.infra.ai.prompt.prompt_manager - INFO - prompt_manager.py:47 - Loaded 5 system prompts from C:\workspace\side\ai-agent\ai-interface\prompts\system
2025-09-23 15:40:41 - app - INFO - __init__.py:23 - 로깅 설정 완료
2025-09-23 15:40:41 - app - INFO - __init__.py:24 - 로그 디렉토리: C:\workspace\side\ai-agent\ai-interface\app\data\logs
2025-09-23 15:40:41 - app.infra.docker.client - INFO - client.py:32 - Docker 클라이언트 초기화 완료
2025-09-23 15:40:42 - app.infra.ai.prompt.prompt_manager - INFO - prompt_manager.py:47 - Loaded 5 system prompts from C:\workspace\side\ai-agent\ai-interface\prompts\system
2025-09-23 15:45:15 - app - INFO - __init__.py:23 - 로깅 설정 완료
2025-09-23 15:45:15 - app - INFO - __init__.py:24 - 로그 디렉토리: C:\workspace\side\ai-agent\ai-interface\app\data\logs
2025-09-23 15:45:15 - app.infra.docker.client - INFO - client.py:32 - Docker 클라이언트 초기화 완료
2025-09-23 15:45:15 - app.infra.ai.prompt.prompt_manager - INFO - prompt_manager.py:47 - Loaded 5 system prompts from C:\workspace\side\ai-agent\ai-interface\prompts\system
2025-09-23 15:46:37 - app - INFO - __init__.py:23 - 로깅 설정 완료
2025-09-23 15:46:37 - app - INFO - __init__.py:24 - 로그 디렉토리: C:\workspace\side\ai-agent\ai-interface\app\data\logs
2025-09-23 15:46:37 - app.infra.docker.client - INFO - client.py:32 - Docker 클라이언트 초기화 완료
2025-09-23 15:46:37 - app.infra.ai.prompt.prompt_manager - INFO - prompt_manager.py:47 - Loaded 5 system prompts from C:\workspace\side\ai-agent\ai-interface\prompts\system
2025-09-23 16:16:39 - app - INFO - __init__.py:23 - 로깅 설정 완료
2025-09-23 16:16:39 - app - INFO - __init__.py:24 - 로그 디렉토리: C:\workspace\side\ai-agent\ai-interface\app\data\logs
2025-09-23 16:16:39 - app.infra.docker.client - INFO - client.py:32 - Docker 클라이언트 초기화 완료
2025-09-23 16:16:39 - app.infra.ai.prompt.prompt_manager - INFO - prompt_manager.py:47 - Loaded 5 system prompts from C:\workspace\side\ai-agent\ai-interface\prompts\system
2025-09-23 16:18:05 - app - INFO - __init__.py:23 - 로깅 설정 완료
2025-09-23 16:18:05 - app - INFO - __init__.py:24 - 로그 디렉토리: C:\workspace\side\ai-agent\ai-interface\app\data\logs
2025-09-23 16:18:05 - app.infra.docker.client - INFO - client.py:32 - Docker 클라이언트 초기화 완료
2025-09-23 16:18:05 - app.infra.ai.prompt.prompt_manager - INFO - prompt_manager.py:47 - Loaded 5 system prompts from C:\workspace\side\ai-agent\ai-interface\prompts\system
2025-09-23 16:19:47 - app - INFO - __init__.py:23 - 로깅 설정 완료
2025-09-23 16:19:47 - app - INFO - __init__.py:24 - 로그 디렉토리: C:\workspace\side\ai-agent\ai-interface\app\data\logs
2025-09-23 16:19:47 - app.infra.docker.client - INFO - client.py:32 - Docker 클라이언트 초기화 완료
2025-09-23 16:19:47 - app.infra.ai.prompt.prompt_manager - INFO - prompt_manager.py:47 - Loaded 5 system prompts from C:\workspace\side\ai-agent\ai-interface\prompts\system
2025-09-23 16:21:00 - app.domains.file.service - INFO - service.py:45 - 파일 처리 시작: 일자별_대출_조회_현황_통계정보.xlsx, 크기: 10554 bytes, 해시: 0cc9e746feb4d5e9...
2025-09-23 16:21:01 - app.domains.file.service - INFO - service.py:64 - 파일 처리 완료: 일자별_대출_조회_현황_통계정보.xlsx
2025-09-23 16:21:07 - app.domains.code.service - ERROR - service.py:54 - 코드 생성 실패: 1 validation error for LLMRequest
file_content
  Input should be a valid string [type=string_type, input_value={'Sheet1': ExcelSheetInfo...상)'], shape=(12, 12))}, input_type=dict]
    For further information visit https://errors.pydantic.dev/2.11/v/string_type
2025-09-23 16:21:32 - app.domains.file.service - INFO - service.py:45 - 파일 처리 시작: 일자별_대출_조회_현황_통계정보.xlsx, 크기: 10554 bytes, 해시: 0cc9e746feb4d5e9...
2025-09-23 16:21:32 - app.domains.file.service - INFO - service.py:64 - 파일 처리 완료: 일자별_대출_조회_현황_통계정보.xlsx
2025-09-23 16:21:35 - app.domains.code.service - ERROR - service.py:54 - 코드 생성 실패: 1 validation error for LLMRequest
file_content
  Input should be a valid string [type=string_type, input_value={'Sheet1': ExcelSheetInfo...상)'], shape=(12, 12))}, input_type=dict]
    For further information visit https://errors.pydantic.dev/2.11/v/string_type
2025-09-23 16:21:36 - app.domains.file.service - INFO - service.py:45 - 파일 처리 시작: 일자별_대출_조회_현황_통계정보.xlsx, 크기: 10554 bytes, 해시: 0cc9e746feb4d5e9...
2025-09-23 16:21:36 - app.domains.file.service - INFO - service.py:64 - 파일 처리 완료: 일자별_대출_조회_현황_통계정보.xlsx
2025-09-23 16:21:50 - app.domains.code.service - ERROR - service.py:54 - 코드 생성 실패: 1 validation error for LLMRequest
file_content
  Input should be a valid string [type=string_type, input_value={'Sheet1': ExcelSheetInfo...상)'], shape=(12, 12))}, input_type=dict]
    For further information visit https://errors.pydantic.dev/2.11/v/string_type
2025-09-23 16:23:15 - app - INFO - __init__.py:23 - 로깅 설정 완료
2025-09-23 16:23:15 - app - INFO - __init__.py:24 - 로그 디렉토리: C:\workspace\side\ai-agent\ai-interface\app\data\logs
2025-09-23 16:23:15 - app.infra.docker.client - INFO - client.py:32 - Docker 클라이언트 초기화 완료
2025-09-23 16:23:15 - app.infra.ai.prompt.prompt_manager - INFO - prompt_manager.py:47 - Loaded 5 system prompts from C:\workspace\side\ai-agent\ai-interface\prompts\system
2025-09-23 16:23:16 - app.domains.file.service - INFO - service.py:45 - 파일 처리 시작: 일자별_대출_조회_현황_통계정보.xlsx, 크기: 10554 bytes, 해시: 0cc9e746feb4d5e9...
2025-09-23 16:23:16 - app.domains.file.service - INFO - service.py:64 - 파일 처리 완료: 일자별_대출_조회_현황_통계정보.xlsx
2025-09-23 16:23:41 - app.infra.ai.llm.llm_manager - ERROR - llm_manager.py:64 - Failed to generate response: 'NoneType' object has no attribute 'model_name'
2025-09-23 16:23:41 - app.domains.code.service - ERROR - service.py:54 - 코드 생성 실패: Failed to generate response: 'NoneType' object has no attribute 'model_name'
2025-09-23 16:24:46 - app - INFO - __init__.py:23 - 로깅 설정 완료
2025-09-23 16:24:46 - app - INFO - __init__.py:24 - 로그 디렉토리: C:\workspace\side\ai-agent\ai-interface\app\data\logs
2025-09-23 16:24:46 - app.infra.docker.client - INFO - client.py:32 - Docker 클라이언트 초기화 완료
2025-09-23 16:24:46 - app.infra.ai.prompt.prompt_manager - INFO - prompt_manager.py:47 - Loaded 5 system prompts from C:\workspace\side\ai-agent\ai-interface\prompts\system
2025-09-23 16:24:48 - app.domains.file.service - INFO - service.py:45 - 파일 처리 시작: 일자별_대출_조회_현황_통계정보.xlsx, 크기: 10554 bytes, 해시: 0cc9e746feb4d5e9...
2025-09-23 16:24:48 - app.domains.file.service - INFO - service.py:64 - 파일 처리 완료: 일자별_대출_조회_현황_통계정보.xlsx
2025-09-23 16:25:12 - app.domains.code.service - ERROR - service.py:54 - 코드 생성 실패: 'LLMResponse' object has no attribute 'data'
2025-09-23 16:27:21 - app - INFO - __init__.py:23 - 로깅 설정 완료
2025-09-23 16:27:21 - app - INFO - __init__.py:24 - 로그 디렉토리: C:\workspace\side\ai-agent\ai-interface\app\data\logs
2025-09-23 16:27:21 - app.infra.docker.client - INFO - client.py:32 - Docker 클라이언트 초기화 완료
2025-09-23 16:27:21 - app.infra.ai.prompt.prompt_manager - INFO - prompt_manager.py:47 - Loaded 5 system prompts from C:\workspace\side\ai-agent\ai-interface\prompts\system
2025-09-23 16:27:47 - app.domains.file.service - INFO - service.py:45 - 파일 처리 시작: 일자별_대출_조회_현황_통계정보.xlsx, 크기: 10554 bytes, 해시: 0cc9e746feb4d5e9...
2025-09-23 16:27:50 - app.domains.file.service - INFO - service.py:64 - 파일 처리 완료: 일자별_대출_조회_현황_통계정보.xlsx
2025-09-23 16:29:44 - app.domains.code.service - ERROR - service.py:54 - 코드 생성 실패: 'LLMResponse' object has no attribute 'data'
2025-09-23 16:32:53 - app - INFO - __init__.py:23 - 로깅 설정 완료
2025-09-23 16:32:53 - app - INFO - __init__.py:24 - 로그 디렉토리: C:\workspace\side\ai-agent\ai-interface\app\data\logs
2025-09-23 16:32:53 - app.infra.docker.client - INFO - client.py:32 - Docker 클라이언트 초기화 완료
2025-09-23 16:32:53 - app.infra.ai.prompt.prompt_manager - INFO - prompt_manager.py:47 - Loaded 5 system prompts from C:\workspace\side\ai-agent\ai-interface\prompts\system
2025-09-23 16:32:54 - app.domains.file.service - INFO - service.py:45 - 파일 처리 시작: 일자별_대출_조회_현황_통계정보.xlsx, 크기: 10554 bytes, 해시: 0cc9e746feb4d5e9...
2025-09-23 16:32:57 - app.domains.file.service - INFO - service.py:64 - 파일 처리 완료: 일자별_대출_조회_현황_통계정보.xlsx
2025-09-23 16:33:02 - app.domains.code.service - ERROR - service.py:54 - 코드 생성 실패: 1 validation error for LLMRequest
file_content
  Input should be a valid string [type=string_type, input_value={'Sheet1': ExcelSheetInfo...상)'], shape=(12, 12))}, input_type=dict]
    For further information visit https://errors.pydantic.dev/2.11/v/string_type
2025-09-23 16:34:28 - app - INFO - __init__.py:23 - 로깅 설정 완료
2025-09-23 16:34:28 - app - INFO - __init__.py:24 - 로그 디렉토리: C:\workspace\side\ai-agent\ai-interface\app\data\logs
2025-09-23 16:34:28 - app.infra.docker.client - INFO - client.py:32 - Docker 클라이언트 초기화 완료
2025-09-23 16:34:28 - app.infra.ai.prompt.prompt_manager - INFO - prompt_manager.py:47 - Loaded 5 system prompts from C:\workspace\side\ai-agent\ai-interface\prompts\system
2025-09-23 16:34:42 - app.domains.file.service - INFO - service.py:45 - 파일 처리 시작: 일자별_대출_조회_현황_통계정보.xlsx, 크기: 10554 bytes, 해시: 0cc9e746feb4d5e9...
2025-09-23 16:34:42 - app.domains.file.service - INFO - service.py:64 - 파일 처리 완료: 일자별_대출_조회_현황_통계정보.xlsx
2025-09-23 16:35:42 - app.domains.code.service - ERROR - service.py:54 - 코드 생성 실패: 'LLMResponse' object has no attribute 'data'
2025-09-23 16:36:44 - app - INFO - __init__.py:23 - 로깅 설정 완료
2025-09-23 16:36:44 - app - INFO - __init__.py:24 - 로그 디렉토리: C:\workspace\side\ai-agent\ai-interface\app\data\logs
2025-09-23 16:36:44 - app.infra.docker.client - INFO - client.py:32 - Docker 클라이언트 초기화 완료
2025-09-23 16:36:44 - app.infra.ai.prompt.prompt_manager - INFO - prompt_manager.py:47 - Loaded 5 system prompts from C:\workspace\side\ai-agent\ai-interface\prompts\system
2025-09-23 16:36:49 - app.domains.file.service - INFO - service.py:45 - 파일 처리 시작: 일자별_대출_조회_현황_통계정보.xlsx, 크기: 10554 bytes, 해시: 0cc9e746feb4d5e9...
2025-09-23 16:36:49 - app.domains.file.service - INFO - service.py:64 - 파일 처리 완료: 일자별_대출_조회_현황_통계정보.xlsx
2025-09-23 16:42:24 - app.domains.file.service - INFO - service.py:45 - 파일 처리 시작: 일자별_대출_조회_현황_통계정보.xlsx, 크기: 10554 bytes, 해시: 0cc9e746feb4d5e9...
2025-09-23 16:42:24 - app.domains.file.service - INFO - service.py:64 - 파일 처리 완료: 일자별_대출_조회_현황_통계정보.xlsx
2025-09-23 16:44:46 - app.infra.docker.client - INFO - client.py:45 - 이미지 존재 확인: jupyter/scipy-notebook:latest
2025-09-23 16:46:42 - app - INFO - __init__.py:23 - 로깅 설정 완료
2025-09-23 16:46:42 - app - INFO - __init__.py:24 - 로그 디렉토리: C:\workspace\side\ai-agent\ai-interface\app\data\logs
2025-09-23 16:46:42 - app.infra.docker.client - INFO - client.py:32 - Docker 클라이언트 초기화 완료
2025-09-23 16:46:42 - app.infra.ai.prompt.prompt_manager - INFO - prompt_manager.py:47 - Loaded 5 system prompts from C:\workspace\side\ai-agent\ai-interface\prompts\system
2025-09-23 16:55:25 - app - INFO - __init__.py:23 - 로깅 설정 완료
2025-09-23 16:55:25 - app - INFO - __init__.py:24 - 로그 디렉토리: C:\workspace\side\ai-agent\ai-interface\app\data\logs
2025-09-23 16:55:25 - app.infra.docker.client - INFO - client.py:32 - Docker 클라이언트 초기화 완료
2025-09-23 16:55:25 - app.infra.ai.prompt.prompt_manager - INFO - prompt_manager.py:47 - Loaded 5 system prompts from C:\workspace\side\ai-agent\ai-interface\prompts\system
2025-09-23 16:55:28 - app.domains.file.service - INFO - service.py:49 - 파일 처리 시작: 일자별_대출_조회_현황_통계정보.xlsx, 크기: 10554 bytes, 해시: 0cc9e746feb4d5e9...
2025-09-23 16:55:29 - app.domains.file.service - INFO - service.py:68 - 파일 처리 완료: 일자별_대출_조회_현황_통계정보.xlsx
2025-09-23 16:56:54 - app.infra.docker.client - INFO - client.py:45 - 이미지 존재 확인: jupyter/scipy-notebook:latest
2025-09-23 16:57:50 - app.infra.docker.client - INFO - client.py:45 - 이미지 존재 확인: jupyter/scipy-notebook:latest
2025-09-23 16:58:20 - app.domains.file.service - INFO - service.py:49 - 파일 처리 시작: 일자별_대출_조회_현황_통계정보.xlsx, 크기: 10554 bytes, 해시: 0cc9e746feb4d5e9...
2025-09-23 16:58:20 - app.domains.file.service - INFO - service.py:68 - 파일 처리 완료: 일자별_대출_조회_현황_통계정보.xlsx
2025-09-23 16:58:24 - app - INFO - __init__.py:23 - 로깅 설정 완료
2025-09-23 16:58:24 - app - INFO - __init__.py:24 - 로그 디렉토리: C:\workspace\side\ai-agent\ai-interface\app\data\logs
2025-09-23 16:58:24 - app.infra.docker.client - INFO - client.py:32 - Docker 클라이언트 초기화 완료
2025-09-23 16:58:24 - app.infra.ai.prompt.prompt_manager - INFO - prompt_manager.py:47 - Loaded 5 system prompts from C:\workspace\side\ai-agent\ai-interface\prompts\system
2025-09-23 16:58:41 - app.domains.file.service - INFO - service.py:49 - 파일 처리 시작: 일자별_대출_조회_현황_통계정보.xlsx, 크기: 10554 bytes, 해시: 0cc9e746feb4d5e9...
2025-09-23 16:58:41 - app.domains.file.service - INFO - service.py:68 - 파일 처리 완료: 일자별_대출_조회_현황_통계정보.xlsx
2025-09-23 17:00:09 - app - INFO - __init__.py:23 - 로깅 설정 완료
2025-09-23 17:00:09 - app - INFO - __init__.py:24 - 로그 디렉토리: C:\workspace\side\ai-agent\ai-interface\app\data\logs
2025-09-23 17:00:09 - app.infra.docker.client - INFO - client.py:32 - Docker 클라이언트 초기화 완료
2025-09-23 17:00:09 - app.infra.ai.prompt.prompt_manager - INFO - prompt_manager.py:47 - Loaded 5 system prompts from C:\workspace\side\ai-agent\ai-interface\prompts\system
2025-09-23 17:16:12 - app - INFO - __init__.py:23 - 로깅 설정 완료
2025-09-23 17:16:12 - app - INFO - __init__.py:24 - 로그 디렉토리: C:\workspace\side\ai-agent\ai-interface\app\data\logs
2025-09-23 17:16:12 - app.infra.docker.client - INFO - client.py:32 - Docker 클라이언트 초기화 완료
2025-09-23 17:16:12 - app.infra.ai.prompt.prompt_manager - INFO - prompt_manager.py:47 - Loaded 5 system prompts from C:\workspace\side\ai-agent\ai-interface\prompts\system
2025-09-23 17:16:15 - app.domains.vector.dependencies - INFO - dependencies.py:40 - 벡터 리포지토리 초기화 완료
2025-09-23 17:16:15 - app.domains.vector.dependencies - INFO - dependencies.py:53 - 벡터 서비스 초기화 완료
2025-09-23 17:16:15 - app.domains.vector.repository - ERROR - repository.py:423 - 컬렉션 목록 조회 실패: 연결이 초기화되지 않았습니다.
2025-09-23 17:16:18 - app.core.database.vector_connection - INFO - vector_connection.py:64 - 임베딩 모델 'bge-m3:567m-fp16' 연결 성공
2025-09-23 17:16:18 - app.core.database.vector_connection - INFO - vector_connection.py:65 - 임베딩 차원: 1024
2025-09-23 17:16:18 - app.core.database.vector_connection - INFO - vector_connection.py:106 - PostgreSQL 연결 성공: PostgreSQL 17.6 (Debian 17.6-1.pgdg12+1) on x86_64-pc-linux-gnu, compiled by gcc (Debian 12.2.0-14+deb12u1) 12.2.0, 64-bit
2025-09-23 17:16:18 - app.core.database.vector_connection - INFO - vector_connection.py:134 - pgvector 확장이 이미 설치되어 있습니다
2025-09-23 17:16:18 - app.core.database.vector_connection - INFO - vector_connection.py:46 - 벡터 DB 연결 초기화 완료
2025-09-23 17:16:18 - app.domains.vector.dependencies - INFO - dependencies.py:28 - 벡터 연결 관리자 초기화 완료
2025-09-23 17:16:18 - app.domains.vector.dependencies - INFO - dependencies.py:40 - 벡터 리포지토리 초기화 완료
2025-09-23 17:16:18 - app.domains.vector.dependencies - INFO - dependencies.py:53 - 벡터 서비스 초기화 완료
2025-09-23 17:16:18 - app.core.database.vector_connection - INFO - vector_connection.py:192 - 벡터스토어 생성: collection='documents'
2025-09-23 17:16:18 - app.core.database.vector_connection - ERROR - vector_connection.py:225 - 벡터스토어 정보 조회 실패: (sqlalchemy.dialects.postgresql.asyncpg.ProgrammingError) <class 'asyncpg.exceptions.UndefinedTableError'>: relation "langchain_pg_embedding_documents" does not exist
[SQL: 
                    SELECT
                        COUNT(*) as document_count,
                        pg_size_pretty(pg_total_relation_size('langchain_pg_embedding_documents')) as table_size
                    FROM langchain_pg_embedding_documents
                ]
(Background on this error at: https://sqlalche.me/e/20/f405)
2025-09-23 17:17:05 - app.domains.vector.service - INFO - service.py:102 - 문서를 3개 청크로 분할 완료
2025-09-23 17:17:05 - app.domains.vector.repository - INFO - repository.py:60 - 총 3개 문서를 컬렉션 'default'에 저장 완료
2025-09-23 17:17:05 - app.core.database.vector_connection - ERROR - vector_connection.py:225 - 벡터스토어 정보 조회 실패: (sqlalchemy.dialects.postgresql.asyncpg.ProgrammingError) <class 'asyncpg.exceptions.UndefinedTableError'>: relation "langchain_pg_embedding_documents" does not exist
[SQL: 
                    SELECT
                        COUNT(*) as document_count,
                        pg_size_pretty(pg_total_relation_size('langchain_pg_embedding_documents')) as table_size
                    FROM langchain_pg_embedding_documents
                ]
(Background on this error at: https://sqlalche.me/e/20/f405)
2025-09-23 17:17:38 - app.domains.vector.repository - INFO - repository.py:105 - 검색 완료: 3개 결과, 142.37ms
2025-09-23 17:17:45 - app.domains.vector.repository - INFO - repository.py:105 - 검색 완료: 3개 결과, 133.80ms
2025-09-23 17:20:01 - app - INFO - __init__.py:23 - 로깅 설정 완료
2025-09-23 17:20:01 - app - INFO - __init__.py:24 - 로그 디렉토리: C:\workspace\side\ai-agent\ai-interface\app\data\logs
2025-09-23 17:20:01 - app.infra.docker.client - INFO - client.py:32 - Docker 클라이언트 초기화 완료
2025-09-23 17:20:01 - app.infra.ai.prompt.prompt_manager - INFO - prompt_manager.py:47 - Loaded 5 system prompts from C:\workspace\side\ai-agent\ai-interface\prompts\system
2025-09-23 17:20:01 - app.domains.vector.dependencies - INFO - dependencies.py:40 - 벡터 리포지토리 초기화 완료
2025-09-23 17:20:01 - app.domains.vector.dependencies - INFO - dependencies.py:53 - 벡터 서비스 초기화 완료
2025-09-23 17:20:01 - app.domains.vector.repository - ERROR - repository.py:423 - 컬렉션 목록 조회 실패: 연결이 초기화되지 않았습니다.
2025-09-23 17:20:01 - app.core.database.vector_connection - INFO - vector_connection.py:64 - 임베딩 모델 'bge-m3:567m-fp16' 연결 성공
2025-09-23 17:20:01 - app.core.database.vector_connection - INFO - vector_connection.py:65 - 임베딩 차원: 1024
2025-09-23 17:20:01 - app.core.database.vector_connection - INFO - vector_connection.py:106 - PostgreSQL 연결 성공: PostgreSQL 17.6 (Debian 17.6-1.pgdg12+1) on x86_64-pc-linux-gnu, compiled by gcc (Debian 12.2.0-14+deb12u1) 12.2.0, 64-bit
2025-09-23 17:20:01 - app.core.database.vector_connection - INFO - vector_connection.py:134 - pgvector 확장이 이미 설치되어 있습니다
2025-09-23 17:20:01 - app.core.database.vector_connection - INFO - vector_connection.py:46 - 벡터 DB 연결 초기화 완료
2025-09-23 17:20:01 - app.domains.vector.dependencies - INFO - dependencies.py:28 - 벡터 연결 관리자 초기화 완료
2025-09-23 17:20:01 - app.domains.vector.dependencies - INFO - dependencies.py:40 - 벡터 리포지토리 초기화 완료
2025-09-23 17:20:01 - app.domains.vector.dependencies - INFO - dependencies.py:53 - 벡터 서비스 초기화 완료
2025-09-23 17:20:01 - app.core.database.vector_connection - INFO - vector_connection.py:192 - 벡터스토어 생성: collection='documents'
2025-09-23 17:20:01 - app.core.database.vector_connection - ERROR - vector_connection.py:225 - 벡터스토어 정보 조회 실패: (sqlalchemy.dialects.postgresql.asyncpg.ProgrammingError) <class 'asyncpg.exceptions.UndefinedTableError'>: relation "langchain_pg_embedding_documents" does not exist
[SQL: 
                    SELECT
                        COUNT(*) as document_count,
                        pg_size_pretty(pg_total_relation_size('langchain_pg_embedding_documents')) as table_size
                    FROM langchain_pg_embedding_documents
                ]
(Background on this error at: https://sqlalche.me/e/20/f405)
2025-09-23 17:20:03 - app.domains.vector.repository - INFO - repository.py:105 - 검색 완료: 3개 결과, 115.02ms
2025-09-23 17:20:21 - app.domains.vector.repository - INFO - repository.py:105 - 검색 완료: 3개 결과, 110.23ms
2025-09-23 17:21:06 - app.domains.vector.repository - ERROR - repository.py:423 - 컬렉션 목록 조회 실패: Textual SQL expression '\n                    SELE...' should be explicitly declared as text('\n                    SELE...')
2025-09-23 17:21:06 - app.core.database.vector_connection - ERROR - vector_connection.py:225 - 벡터스토어 정보 조회 실패: (sqlalchemy.dialects.postgresql.asyncpg.ProgrammingError) <class 'asyncpg.exceptions.UndefinedTableError'>: relation "langchain_pg_embedding_documents" does not exist
[SQL: 
                    SELECT
                        COUNT(*) as document_count,
                        pg_size_pretty(pg_total_relation_size('langchain_pg_embedding_documents')) as table_size
                    FROM langchain_pg_embedding_documents
                ]
(Background on this error at: https://sqlalche.me/e/20/f405)
2025-09-23 17:21:19 - app.domains.vector.repository - ERROR - repository.py:423 - 컬렉션 목록 조회 실패: Textual SQL expression '\n                    SELE...' should be explicitly declared as text('\n                    SELE...')
2025-09-23 17:21:19 - app.core.database.vector_connection - ERROR - vector_connection.py:225 - 벡터스토어 정보 조회 실패: (sqlalchemy.dialects.postgresql.asyncpg.ProgrammingError) <class 'asyncpg.exceptions.UndefinedTableError'>: relation "langchain_pg_embedding_documents" does not exist
[SQL: 
                    SELECT
                        COUNT(*) as document_count,
                        pg_size_pretty(pg_total_relation_size('langchain_pg_embedding_documents')) as table_size
                    FROM langchain_pg_embedding_documents
                ]
(Background on this error at: https://sqlalche.me/e/20/f405)
2025-09-23 17:22:39 - app.domains.vector.repository - ERROR - repository.py:423 - 컬렉션 목록 조회 실패: Textual SQL expression '\n                    SELE...' should be explicitly declared as text('\n                    SELE...')
2025-09-23 17:22:39 - app.core.database.vector_connection - ERROR - vector_connection.py:225 - 벡터스토어 정보 조회 실패: (sqlalchemy.dialects.postgresql.asyncpg.ProgrammingError) <class 'asyncpg.exceptions.UndefinedTableError'>: relation "langchain_pg_embedding_documents" does not exist
[SQL: 
                    SELECT
                        COUNT(*) as document_count,
                        pg_size_pretty(pg_total_relation_size('langchain_pg_embedding_documents')) as table_size
                    FROM langchain_pg_embedding_documents
                ]
(Background on this error at: https://sqlalche.me/e/20/f405)
2025-09-23 17:23:06 - app.domains.vector.repository - ERROR - repository.py:423 - 컬렉션 목록 조회 실패: Textual SQL expression '\n                    SELE...' should be explicitly declared as text('\n                    SELE...')
2025-09-23 17:23:07 - app.core.database.vector_connection - ERROR - vector_connection.py:225 - 벡터스토어 정보 조회 실패: (sqlalchemy.dialects.postgresql.asyncpg.ProgrammingError) <class 'asyncpg.exceptions.UndefinedTableError'>: relation "langchain_pg_embedding_documents" does not exist
[SQL: 
                    SELECT
                        COUNT(*) as document_count,
                        pg_size_pretty(pg_total_relation_size('langchain_pg_embedding_documents')) as table_size
                    FROM langchain_pg_embedding_documents
                ]
(Background on this error at: https://sqlalche.me/e/20/f405)
2025-09-23 17:24:13 - app.domains.vector.repository - ERROR - repository.py:423 - 컬렉션 목록 조회 실패: Textual SQL expression '\n                    SELE...' should be explicitly declared as text('\n                    SELE...')
2025-09-23 17:24:13 - app.core.database.vector_connection - ERROR - vector_connection.py:225 - 벡터스토어 정보 조회 실패: (sqlalchemy.dialects.postgresql.asyncpg.ProgrammingError) <class 'asyncpg.exceptions.UndefinedTableError'>: relation "langchain_pg_embedding_documents" does not exist
[SQL: 
                    SELECT
                        COUNT(*) as document_count,
                        pg_size_pretty(pg_total_relation_size('langchain_pg_embedding_documents')) as table_size
                    FROM langchain_pg_embedding_documents
                ]
(Background on this error at: https://sqlalche.me/e/20/f405)
2025-09-23 17:24:22 - app.domains.vector.repository - ERROR - repository.py:423 - 컬렉션 목록 조회 실패: Textual SQL expression '\n                    SELE...' should be explicitly declared as text('\n                    SELE...')
2025-09-23 17:24:22 - app.core.database.vector_connection - ERROR - vector_connection.py:225 - 벡터스토어 정보 조회 실패: (sqlalchemy.dialects.postgresql.asyncpg.ProgrammingError) <class 'asyncpg.exceptions.UndefinedTableError'>: relation "langchain_pg_embedding_documents" does not exist
[SQL: 
                    SELECT
                        COUNT(*) as document_count,
                        pg_size_pretty(pg_total_relation_size('langchain_pg_embedding_documents')) as table_size
                    FROM langchain_pg_embedding_documents
                ]
(Background on this error at: https://sqlalche.me/e/20/f405)
2025-09-23 17:24:36 - app.domains.vector.repository - ERROR - repository.py:423 - 컬렉션 목록 조회 실패: Textual SQL expression '\n                    SELE...' should be explicitly declared as text('\n                    SELE...')
2025-09-23 17:24:37 - app.core.database.vector_connection - ERROR - vector_connection.py:225 - 벡터스토어 정보 조회 실패: (sqlalchemy.dialects.postgresql.asyncpg.ProgrammingError) <class 'asyncpg.exceptions.UndefinedTableError'>: relation "langchain_pg_embedding_documents" does not exist
[SQL: 
                    SELECT
                        COUNT(*) as document_count,
                        pg_size_pretty(pg_total_relation_size('langchain_pg_embedding_documents')) as table_size
                    FROM langchain_pg_embedding_documents
                ]
(Background on this error at: https://sqlalche.me/e/20/f405)
2025-09-23 17:38:57 - app - INFO - __init__.py:23 - 로깅 설정 완료
2025-09-23 17:38:57 - app - INFO - __init__.py:24 - 로그 디렉토리: C:\workspace\side\ai-agent\ai-interface\app\data\logs
2025-09-23 17:38:57 - app.infra.docker.client - INFO - client.py:32 - Docker 클라이언트 초기화 완료
2025-09-23 17:38:57 - app.infra.ai.prompt.prompt_manager - INFO - prompt_manager.py:47 - Loaded 5 system prompts from C:\workspace\side\ai-agent\ai-interface\prompts\system
2025-09-23 17:39:10 - app.domains.vector.dependencies - INFO - dependencies.py:40 - 벡터 리포지토리 초기화 완료
2025-09-23 17:39:10 - app.domains.vector.dependencies - INFO - dependencies.py:53 - 벡터 서비스 초기화 완료
2025-09-23 17:39:10 - app.domains.vector.repository - ERROR - repository.py:423 - 컬렉션 목록 조회 실패: 연결이 초기화되지 않았습니다.
2025-09-23 17:39:10 - app.core.database.vector_connection - INFO - vector_connection.py:64 - 임베딩 모델 'bge-m3:567m-fp16' 연결 성공
2025-09-23 17:39:10 - app.core.database.vector_connection - INFO - vector_connection.py:65 - 임베딩 차원: 1024
2025-09-23 17:39:10 - app.core.database.vector_connection - INFO - vector_connection.py:106 - PostgreSQL 연결 성공: PostgreSQL 17.6 (Debian 17.6-1.pgdg12+1) on x86_64-pc-linux-gnu, compiled by gcc (Debian 12.2.0-14+deb12u1) 12.2.0, 64-bit
2025-09-23 17:39:10 - app.core.database.vector_connection - INFO - vector_connection.py:134 - pgvector 확장이 이미 설치되어 있습니다
2025-09-23 17:39:10 - app.core.database.vector_connection - INFO - vector_connection.py:46 - 벡터 DB 연결 초기화 완료
2025-09-23 17:39:10 - app.domains.vector.dependencies - INFO - dependencies.py:28 - 벡터 연결 관리자 초기화 완료
2025-09-23 17:39:10 - app.domains.vector.dependencies - INFO - dependencies.py:40 - 벡터 리포지토리 초기화 완료
2025-09-23 17:39:10 - app.domains.vector.dependencies - INFO - dependencies.py:53 - 벡터 서비스 초기화 완료
2025-09-23 17:39:10 - app.core.database.vector_connection - INFO - vector_connection.py:192 - 벡터스토어 생성: collection='documents'
2025-09-23 17:39:10 - app.core.database.vector_connection - ERROR - vector_connection.py:225 - 벡터스토어 정보 조회 실패: (sqlalchemy.dialects.postgresql.asyncpg.ProgrammingError) <class 'asyncpg.exceptions.UndefinedTableError'>: relation "langchain_pg_embedding_documents" does not exist
[SQL: 
                    SELECT
                        COUNT(*) as document_count,
                        pg_size_pretty(pg_total_relation_size('langchain_pg_embedding_documents')) as table_size
                    FROM langchain_pg_embedding_documents
                ]
(Background on this error at: https://sqlalche.me/e/20/f405)
2025-09-23 17:41:52 - app - INFO - __init__.py:23 - 로깅 설정 완료
2025-09-23 17:41:52 - app - INFO - __init__.py:24 - 로그 디렉토리: C:\workspace\side\ai-agent\ai-interface\app\data\logs
2025-09-23 17:41:52 - app.infra.docker.client - INFO - client.py:32 - Docker 클라이언트 초기화 완료
2025-09-23 17:41:52 - app.infra.ai.prompt.prompt_manager - INFO - prompt_manager.py:47 - Loaded 5 system prompts from C:\workspace\side\ai-agent\ai-interface\prompts\system
2025-09-23 17:42:00 - app.domains.vector.dependencies - INFO - dependencies.py:40 - 벡터 리포지토리 초기화 완료
2025-09-23 17:42:00 - app.domains.vector.dependencies - INFO - dependencies.py:53 - 벡터 서비스 초기화 완료
2025-09-23 17:42:00 - app.domains.vector.repository - ERROR - repository.py:423 - 컬렉션 목록 조회 실패: 연결이 초기화되지 않았습니다.
2025-09-23 17:42:00 - app.core.database.vector_connection - INFO - vector_connection.py:64 - 임베딩 모델 'bge-m3:567m-fp16' 연결 성공
2025-09-23 17:42:00 - app.core.database.vector_connection - INFO - vector_connection.py:65 - 임베딩 차원: 1024
2025-09-23 17:42:00 - app.core.database.vector_connection - INFO - vector_connection.py:106 - PostgreSQL 연결 성공: PostgreSQL 17.6 (Debian 17.6-1.pgdg12+1) on x86_64-pc-linux-gnu, compiled by gcc (Debian 12.2.0-14+deb12u1) 12.2.0, 64-bit
2025-09-23 17:42:00 - app.core.database.vector_connection - INFO - vector_connection.py:134 - pgvector 확장이 이미 설치되어 있습니다
2025-09-23 17:42:00 - app.core.database.vector_connection - INFO - vector_connection.py:46 - 벡터 DB 연결 초기화 완료
2025-09-23 17:42:00 - app.domains.vector.dependencies - INFO - dependencies.py:28 - 벡터 연결 관리자 초기화 완료
2025-09-23 17:42:00 - app.domains.vector.dependencies - INFO - dependencies.py:40 - 벡터 리포지토리 초기화 완료
2025-09-23 17:42:00 - app.domains.vector.dependencies - INFO - dependencies.py:53 - 벡터 서비스 초기화 완료
2025-09-23 17:42:00 - app.core.database.vector_connection - INFO - vector_connection.py:192 - 벡터스토어 생성: collection='documents'
2025-09-23 17:42:00 - app.core.database.vector_connection - ERROR - vector_connection.py:225 - 벡터스토어 정보 조회 실패: (sqlalchemy.dialects.postgresql.asyncpg.ProgrammingError) <class 'asyncpg.exceptions.UndefinedTableError'>: relation "langchain_pg_embedding_documents" does not exist
[SQL: 
                    SELECT
                        COUNT(*) as document_count,
                        pg_size_pretty(pg_total_relation_size('langchain_pg_embedding_documents')) as table_size
                    FROM langchain_pg_embedding_documents
                ]
(Background on this error at: https://sqlalche.me/e/20/f405)
2025-09-23 17:47:40 - app - INFO - __init__.py:23 - 로깅 설정 완료
2025-09-23 17:47:40 - app - INFO - __init__.py:24 - 로그 디렉토리: C:\workspace\side\ai-agent\ai-interface\app\data\logs
2025-09-23 17:47:40 - app.infra.docker.client - INFO - client.py:32 - Docker 클라이언트 초기화 완료
2025-09-23 17:47:40 - app.infra.ai.prompt.prompt_manager - INFO - prompt_manager.py:47 - Loaded 5 system prompts from C:\workspace\side\ai-agent\ai-interface\prompts\system
2025-09-23 17:47:46 - app.domains.vector.dependencies - INFO - dependencies.py:40 - 벡터 리포지토리 초기화 완료
2025-09-23 17:47:46 - app.domains.vector.dependencies - INFO - dependencies.py:53 - 벡터 서비스 초기화 완료
2025-09-23 17:47:46 - app.domains.vector.repository - ERROR - repository.py:423 - 컬렉션 목록 조회 실패: 연결이 초기화되지 않았습니다.
2025-09-23 17:47:46 - app.core.database.vector_connection - INFO - vector_connection.py:64 - 임베딩 모델 'bge-m3:567m-fp16' 연결 성공
2025-09-23 17:47:46 - app.core.database.vector_connection - INFO - vector_connection.py:65 - 임베딩 차원: 1024
2025-09-23 17:47:46 - app.core.database.vector_connection - INFO - vector_connection.py:106 - PostgreSQL 연결 성공: PostgreSQL 17.6 (Debian 17.6-1.pgdg12+1) on x86_64-pc-linux-gnu, compiled by gcc (Debian 12.2.0-14+deb12u1) 12.2.0, 64-bit
2025-09-23 17:47:47 - app.core.database.vector_connection - INFO - vector_connection.py:134 - pgvector 확장이 이미 설치되어 있습니다
2025-09-23 17:47:47 - app.core.database.vector_connection - INFO - vector_connection.py:46 - 벡터 DB 연결 초기화 완료
2025-09-23 17:47:47 - app.domains.vector.dependencies - INFO - dependencies.py:28 - 벡터 연결 관리자 초기화 완료
2025-09-23 17:47:47 - app.domains.vector.dependencies - INFO - dependencies.py:40 - 벡터 리포지토리 초기화 완료
2025-09-23 17:47:47 - app.domains.vector.dependencies - INFO - dependencies.py:53 - 벡터 서비스 초기화 완료
2025-09-23 17:47:47 - app.core.database.vector_connection - INFO - vector_connection.py:192 - 벡터스토어 생성: collection='documents'
2025-09-23 17:47:47 - app.core.database.vector_connection - ERROR - vector_connection.py:225 - 벡터스토어 정보 조회 실패: (sqlalchemy.dialects.postgresql.asyncpg.ProgrammingError) <class 'asyncpg.exceptions.UndefinedTableError'>: relation "langchain_pg_embedding_documents" does not exist
[SQL: 
                    SELECT
                        COUNT(*) as document_count,
                        pg_size_pretty(pg_total_relation_size('langchain_pg_embedding_documents')) as table_size
                    FROM langchain_pg_embedding_documents
                ]
(Background on this error at: https://sqlalche.me/e/20/f405)
2025-09-23 17:47:58 - app.domains.file.service - INFO - service.py:49 - 파일 처리 시작: 스마트워크플레이스_샘플데이터.txt, 크기: 4655 bytes, 해시: f42ce48087e118e2...
2025-09-23 17:47:58 - app.domains.file.service - INFO - service.py:68 - 파일 처리 완료: 스마트워크플레이스_샘플데이터.txt
