2025-09-22 10:30:05 - app.domains.file.service - ERROR - service.py:74 - 예상치 못한 오류: FileExtractor.extract_excel_content() got an unexpected keyword argument 'encoding'
2025-09-22 10:30:35 - app.domains.file.service - ERROR - service.py:74 - 예상치 못한 오류: FileExtractor.extract_excel_content() got an unexpected keyword argument 'encoding'
2025-09-22 10:31:32 - app.domains.file.service - ERROR - service.py:74 - 예상치 못한 오류: FileExtractor.extract_excel_content() got an unexpected keyword argument 'encoding'
2025-09-22 10:32:57 - app.domains.file.service - ERROR - service.py:74 - 예상치 못한 오류: FileExtractor.extract_excel_content() got an unexpected keyword argument 'encoding'
2025-09-22 10:36:12 - app.domains.file.service - ERROR - service.py:114 - 다중 파일 처리 오류: 'TextExtractionResult' object does not support item assignment
2025-09-22 10:38:17 - app.domains.file.service - ERROR - service.py:114 - 다중 파일 처리 오류: 'TextExtractionResult' object does not support item assignment
2025-09-22 14:58:12 - app.domains.llm.service - ERROR - service.py:55 - 채팅 요청 검증 오류: Failed to get system prompt: Domain 'example' not found
2025-09-22 15:04:48 - app.infra.ai.llm.llm_manager - ERROR - llm_manager.py:62 - Failed to generate response: Cannot connect to host localhost:11434 ssl:default [Multiple exceptions: [Errno 10061] Connect call failed ('::1', 11434, 0, 0), [Errno 10061] Connect call failed ('127.0.0.1', 11434)]
2025-09-22 15:04:48 - app.domains.llm.service - ERROR - service.py:58 - LLM 응답 생성 오류: Failed to generate response: Cannot connect to host localhost:11434 ssl:default [Multiple exceptions: [Errno 10061] Connect call failed ('::1', 11434, 0, 0), [Errno 10061] Connect call failed ('127.0.0.1', 11434)]
2025-09-23 09:43:46 - app.domains.code.service - ERROR - service.py:41 - 코드 생성 실패: 코드 생성 실패: 'NoneType' object has no attribute 'ainvoke'
2025-09-23 09:43:46 - app.api.v1.endpoints.code - ERROR - code.py:33 - 코드 생성 실패: 코드 생성 실패: 'NoneType' object has no attribute 'ainvoke'
2025-09-23 09:43:52 - app.domains.code.service - ERROR - service.py:41 - 코드 생성 실패: 코드 생성 실패: 'NoneType' object has no attribute 'ainvoke'
2025-09-23 09:43:52 - app.api.v1.endpoints.code - ERROR - code.py:33 - 코드 생성 실패: 코드 생성 실패: 'NoneType' object has no attribute 'ainvoke'
2025-09-23 09:48:55 - app.domains.file.service - ERROR - service.py:72 - 파일 추출 오류: I/O operation on closed file.
2025-09-23 09:56:15 - app.domains.file.service - ERROR - service.py:87 - 파일 추출 오류: I/O operation on closed file.
2025-09-23 10:00:08 - app.domains.file.service - ERROR - service.py:87 - 파일 추출 오류: I/O operation on closed file.
2025-09-23 10:04:53 - app.domains.file.service - ERROR - service.py:71 - 파일 추출 오류: I/O operation on closed file.
2025-09-23 10:06:08 - app.domains.file.service - ERROR - service.py:71 - 파일 추출 오류: I/O operation on closed file.
2025-09-23 10:07:24 - app.domains.file.service - ERROR - service.py:71 - 파일 추출 오류: I/O operation on closed file.
2025-09-23 10:17:28 - app.domains.file.service - ERROR - service.py:71 - 파일 추출 오류: Excel 추출 실패: Excel file format cannot be determined, you must specify an engine manually.
2025-09-23 10:23:31 - app.domains.code.service - ERROR - service.py:41 - 코드 생성 실패: 코드 생성 실패: 'NoneType' object has no attribute 'ainvoke'
2025-09-23 10:23:31 - app.api.v1.endpoints.code - ERROR - code.py:22 - 코드 생성 실패: 코드 생성 실패: 'NoneType' object has no attribute 'ainvoke'
2025-09-23 10:23:34 - app.domains.code.service - ERROR - service.py:41 - 코드 생성 실패: 코드 생성 실패: 'NoneType' object has no attribute 'ainvoke'
2025-09-23 10:23:34 - app.api.v1.endpoints.code - ERROR - code.py:22 - 코드 생성 실패: 코드 생성 실패: 'NoneType' object has no attribute 'ainvoke'
2025-09-23 10:23:55 - app.domains.code.service - ERROR - service.py:41 - 코드 생성 실패: 코드 생성 실패: 'NoneType' object has no attribute 'ainvoke'
2025-09-23 10:23:55 - app.api.v1.endpoints.code - ERROR - code.py:22 - 코드 생성 실패: 코드 생성 실패: 'NoneType' object has no attribute 'ainvoke'
2025-09-23 10:40:05 - app.infra.ai.code.code_generator - ERROR - code_generator.py:119 - 코드 생성 실패: 'LLMMetadata' object has no attribute 'model_name'
2025-09-23 10:40:05 - app.domains.code.service - ERROR - service.py:42 - 코드 생성 실패: 코드 생성 실패: 'LLMMetadata' object has no attribute 'model_name'
2025-09-23 10:40:05 - app.api.v1.endpoints.code - ERROR - code.py:22 - 코드 생성 실패: 코드 생성 실패: 'LLMMetadata' object has no attribute 'model_name'
2025-09-23 10:45:40 - app.domains.code.service - ERROR - service.py:65 - 코드 실행 실패: 1 validation error for CodeExecutionResponse
language
  Field required [type=missing, input_value={'execution_id': '2a493d6...nment.DOCKER: 'docker'>}, input_type=dict]
    For further information visit https://errors.pydantic.dev/2.11/v/missing
2025-09-23 10:47:28 - app.domains.code.service - ERROR - service.py:65 - 코드 실행 실패: 1 validation error for CodeExecutionResponse
language
  Field required [type=missing, input_value={'execution_id': '7210879...nment.DOCKER: 'docker'>}, input_type=dict]
    For further information visit https://errors.pydantic.dev/2.11/v/missing
2025-09-23 10:48:07 - app.domains.code.service - ERROR - service.py:65 - 코드 실행 실패: 1 validation error for CodeExecutionResponse
language
  Field required [type=missing, input_value={'execution_id': '1835eac...nment.DOCKER: 'docker'>}, input_type=dict]
    For further information visit https://errors.pydantic.dev/2.11/v/missing
2025-09-23 14:41:55 - app.domains.code.service - ERROR - service.py:64 - 코드 생성 실패: 'Settings' object has no attribute 'default_model_name'
2025-09-23 14:42:20 - app.domains.code.service - ERROR - service.py:64 - 코드 생성 실패: 'Settings' object has no attribute 'default_model_name'
2025-09-23 14:42:36 - app.domains.code.service - ERROR - service.py:64 - 코드 생성 실패: 'Settings' object has no attribute 'default_model_name'
2025-09-23 14:45:21 - app.infra.ai.llm.llm_manager - ERROR - llm_manager.py:63 - Failed to generate response: model 'llama3.1:8b' not found (status code: 404)
2025-09-23 14:45:21 - app.domains.llm.service - ERROR - service.py:85 - LLM 응답 생성 오류: Failed to generate response: model 'llama3.1:8b' not found (status code: 404)
2025-09-23 14:45:23 - app.domains.code.service - ERROR - service.py:61 - 코드 생성 실패: 500: 응답 생성 중 오류가 발생했습니다.
2025-09-23 16:21:07 - app.domains.code.service - ERROR - service.py:54 - 코드 생성 실패: 1 validation error for LLMRequest
file_content
  Input should be a valid string [type=string_type, input_value={'Sheet1': ExcelSheetInfo...상)'], shape=(12, 12))}, input_type=dict]
    For further information visit https://errors.pydantic.dev/2.11/v/string_type
2025-09-23 16:21:35 - app.domains.code.service - ERROR - service.py:54 - 코드 생성 실패: 1 validation error for LLMRequest
file_content
  Input should be a valid string [type=string_type, input_value={'Sheet1': ExcelSheetInfo...상)'], shape=(12, 12))}, input_type=dict]
    For further information visit https://errors.pydantic.dev/2.11/v/string_type
2025-09-23 16:21:50 - app.domains.code.service - ERROR - service.py:54 - 코드 생성 실패: 1 validation error for LLMRequest
file_content
  Input should be a valid string [type=string_type, input_value={'Sheet1': ExcelSheetInfo...상)'], shape=(12, 12))}, input_type=dict]
    For further information visit https://errors.pydantic.dev/2.11/v/string_type
2025-09-23 16:23:41 - app.infra.ai.llm.llm_manager - ERROR - llm_manager.py:64 - Failed to generate response: 'NoneType' object has no attribute 'model_name'
2025-09-23 16:23:41 - app.domains.code.service - ERROR - service.py:54 - 코드 생성 실패: Failed to generate response: 'NoneType' object has no attribute 'model_name'
2025-09-23 16:25:12 - app.domains.code.service - ERROR - service.py:54 - 코드 생성 실패: 'LLMResponse' object has no attribute 'data'
2025-09-23 16:29:44 - app.domains.code.service - ERROR - service.py:54 - 코드 생성 실패: 'LLMResponse' object has no attribute 'data'
2025-09-23 16:33:02 - app.domains.code.service - ERROR - service.py:54 - 코드 생성 실패: 1 validation error for LLMRequest
file_content
  Input should be a valid string [type=string_type, input_value={'Sheet1': ExcelSheetInfo...상)'], shape=(12, 12))}, input_type=dict]
    For further information visit https://errors.pydantic.dev/2.11/v/string_type
2025-09-23 16:35:42 - app.domains.code.service - ERROR - service.py:54 - 코드 생성 실패: 'LLMResponse' object has no attribute 'data'
2025-09-23 17:16:15 - app.domains.vector.repository - ERROR - repository.py:423 - 컬렉션 목록 조회 실패: 연결이 초기화되지 않았습니다.
2025-09-23 17:16:18 - app.core.database.vector_connection - ERROR - vector_connection.py:225 - 벡터스토어 정보 조회 실패: (sqlalchemy.dialects.postgresql.asyncpg.ProgrammingError) <class 'asyncpg.exceptions.UndefinedTableError'>: relation "langchain_pg_embedding_documents" does not exist
[SQL: 
                    SELECT
                        COUNT(*) as document_count,
                        pg_size_pretty(pg_total_relation_size('langchain_pg_embedding_documents')) as table_size
                    FROM langchain_pg_embedding_documents
                ]
(Background on this error at: https://sqlalche.me/e/20/f405)
2025-09-23 17:17:05 - app.core.database.vector_connection - ERROR - vector_connection.py:225 - 벡터스토어 정보 조회 실패: (sqlalchemy.dialects.postgresql.asyncpg.ProgrammingError) <class 'asyncpg.exceptions.UndefinedTableError'>: relation "langchain_pg_embedding_documents" does not exist
[SQL: 
                    SELECT
                        COUNT(*) as document_count,
                        pg_size_pretty(pg_total_relation_size('langchain_pg_embedding_documents')) as table_size
                    FROM langchain_pg_embedding_documents
                ]
(Background on this error at: https://sqlalche.me/e/20/f405)
2025-09-23 17:20:01 - app.domains.vector.repository - ERROR - repository.py:423 - 컬렉션 목록 조회 실패: 연결이 초기화되지 않았습니다.
2025-09-23 17:20:01 - app.core.database.vector_connection - ERROR - vector_connection.py:225 - 벡터스토어 정보 조회 실패: (sqlalchemy.dialects.postgresql.asyncpg.ProgrammingError) <class 'asyncpg.exceptions.UndefinedTableError'>: relation "langchain_pg_embedding_documents" does not exist
[SQL: 
                    SELECT
                        COUNT(*) as document_count,
                        pg_size_pretty(pg_total_relation_size('langchain_pg_embedding_documents')) as table_size
                    FROM langchain_pg_embedding_documents
                ]
(Background on this error at: https://sqlalche.me/e/20/f405)
2025-09-23 17:21:06 - app.domains.vector.repository - ERROR - repository.py:423 - 컬렉션 목록 조회 실패: Textual SQL expression '\n                    SELE...' should be explicitly declared as text('\n                    SELE...')
2025-09-23 17:21:06 - app.core.database.vector_connection - ERROR - vector_connection.py:225 - 벡터스토어 정보 조회 실패: (sqlalchemy.dialects.postgresql.asyncpg.ProgrammingError) <class 'asyncpg.exceptions.UndefinedTableError'>: relation "langchain_pg_embedding_documents" does not exist
[SQL: 
                    SELECT
                        COUNT(*) as document_count,
                        pg_size_pretty(pg_total_relation_size('langchain_pg_embedding_documents')) as table_size
                    FROM langchain_pg_embedding_documents
                ]
(Background on this error at: https://sqlalche.me/e/20/f405)
2025-09-23 17:21:19 - app.domains.vector.repository - ERROR - repository.py:423 - 컬렉션 목록 조회 실패: Textual SQL expression '\n                    SELE...' should be explicitly declared as text('\n                    SELE...')
2025-09-23 17:21:19 - app.core.database.vector_connection - ERROR - vector_connection.py:225 - 벡터스토어 정보 조회 실패: (sqlalchemy.dialects.postgresql.asyncpg.ProgrammingError) <class 'asyncpg.exceptions.UndefinedTableError'>: relation "langchain_pg_embedding_documents" does not exist
[SQL: 
                    SELECT
                        COUNT(*) as document_count,
                        pg_size_pretty(pg_total_relation_size('langchain_pg_embedding_documents')) as table_size
                    FROM langchain_pg_embedding_documents
                ]
(Background on this error at: https://sqlalche.me/e/20/f405)
2025-09-23 17:22:39 - app.domains.vector.repository - ERROR - repository.py:423 - 컬렉션 목록 조회 실패: Textual SQL expression '\n                    SELE...' should be explicitly declared as text('\n                    SELE...')
2025-09-23 17:22:39 - app.core.database.vector_connection - ERROR - vector_connection.py:225 - 벡터스토어 정보 조회 실패: (sqlalchemy.dialects.postgresql.asyncpg.ProgrammingError) <class 'asyncpg.exceptions.UndefinedTableError'>: relation "langchain_pg_embedding_documents" does not exist
[SQL: 
                    SELECT
                        COUNT(*) as document_count,
                        pg_size_pretty(pg_total_relation_size('langchain_pg_embedding_documents')) as table_size
                    FROM langchain_pg_embedding_documents
                ]
(Background on this error at: https://sqlalche.me/e/20/f405)
2025-09-23 17:23:06 - app.domains.vector.repository - ERROR - repository.py:423 - 컬렉션 목록 조회 실패: Textual SQL expression '\n                    SELE...' should be explicitly declared as text('\n                    SELE...')
2025-09-23 17:23:07 - app.core.database.vector_connection - ERROR - vector_connection.py:225 - 벡터스토어 정보 조회 실패: (sqlalchemy.dialects.postgresql.asyncpg.ProgrammingError) <class 'asyncpg.exceptions.UndefinedTableError'>: relation "langchain_pg_embedding_documents" does not exist
[SQL: 
                    SELECT
                        COUNT(*) as document_count,
                        pg_size_pretty(pg_total_relation_size('langchain_pg_embedding_documents')) as table_size
                    FROM langchain_pg_embedding_documents
                ]
(Background on this error at: https://sqlalche.me/e/20/f405)
2025-09-23 17:24:13 - app.domains.vector.repository - ERROR - repository.py:423 - 컬렉션 목록 조회 실패: Textual SQL expression '\n                    SELE...' should be explicitly declared as text('\n                    SELE...')
2025-09-23 17:24:13 - app.core.database.vector_connection - ERROR - vector_connection.py:225 - 벡터스토어 정보 조회 실패: (sqlalchemy.dialects.postgresql.asyncpg.ProgrammingError) <class 'asyncpg.exceptions.UndefinedTableError'>: relation "langchain_pg_embedding_documents" does not exist
[SQL: 
                    SELECT
                        COUNT(*) as document_count,
                        pg_size_pretty(pg_total_relation_size('langchain_pg_embedding_documents')) as table_size
                    FROM langchain_pg_embedding_documents
                ]
(Background on this error at: https://sqlalche.me/e/20/f405)
2025-09-23 17:24:22 - app.domains.vector.repository - ERROR - repository.py:423 - 컬렉션 목록 조회 실패: Textual SQL expression '\n                    SELE...' should be explicitly declared as text('\n                    SELE...')
2025-09-23 17:24:22 - app.core.database.vector_connection - ERROR - vector_connection.py:225 - 벡터스토어 정보 조회 실패: (sqlalchemy.dialects.postgresql.asyncpg.ProgrammingError) <class 'asyncpg.exceptions.UndefinedTableError'>: relation "langchain_pg_embedding_documents" does not exist
[SQL: 
                    SELECT
                        COUNT(*) as document_count,
                        pg_size_pretty(pg_total_relation_size('langchain_pg_embedding_documents')) as table_size
                    FROM langchain_pg_embedding_documents
                ]
(Background on this error at: https://sqlalche.me/e/20/f405)
2025-09-23 17:24:36 - app.domains.vector.repository - ERROR - repository.py:423 - 컬렉션 목록 조회 실패: Textual SQL expression '\n                    SELE...' should be explicitly declared as text('\n                    SELE...')
2025-09-23 17:24:37 - app.core.database.vector_connection - ERROR - vector_connection.py:225 - 벡터스토어 정보 조회 실패: (sqlalchemy.dialects.postgresql.asyncpg.ProgrammingError) <class 'asyncpg.exceptions.UndefinedTableError'>: relation "langchain_pg_embedding_documents" does not exist
[SQL: 
                    SELECT
                        COUNT(*) as document_count,
                        pg_size_pretty(pg_total_relation_size('langchain_pg_embedding_documents')) as table_size
                    FROM langchain_pg_embedding_documents
                ]
(Background on this error at: https://sqlalche.me/e/20/f405)
2025-09-23 17:39:10 - app.domains.vector.repository - ERROR - repository.py:423 - 컬렉션 목록 조회 실패: 연결이 초기화되지 않았습니다.
2025-09-23 17:39:10 - app.core.database.vector_connection - ERROR - vector_connection.py:225 - 벡터스토어 정보 조회 실패: (sqlalchemy.dialects.postgresql.asyncpg.ProgrammingError) <class 'asyncpg.exceptions.UndefinedTableError'>: relation "langchain_pg_embedding_documents" does not exist
[SQL: 
                    SELECT
                        COUNT(*) as document_count,
                        pg_size_pretty(pg_total_relation_size('langchain_pg_embedding_documents')) as table_size
                    FROM langchain_pg_embedding_documents
                ]
(Background on this error at: https://sqlalche.me/e/20/f405)
2025-09-23 17:42:00 - app.domains.vector.repository - ERROR - repository.py:423 - 컬렉션 목록 조회 실패: 연결이 초기화되지 않았습니다.
2025-09-23 17:42:00 - app.core.database.vector_connection - ERROR - vector_connection.py:225 - 벡터스토어 정보 조회 실패: (sqlalchemy.dialects.postgresql.asyncpg.ProgrammingError) <class 'asyncpg.exceptions.UndefinedTableError'>: relation "langchain_pg_embedding_documents" does not exist
[SQL: 
                    SELECT
                        COUNT(*) as document_count,
                        pg_size_pretty(pg_total_relation_size('langchain_pg_embedding_documents')) as table_size
                    FROM langchain_pg_embedding_documents
                ]
(Background on this error at: https://sqlalche.me/e/20/f405)
2025-09-23 17:47:46 - app.domains.vector.repository - ERROR - repository.py:423 - 컬렉션 목록 조회 실패: 연결이 초기화되지 않았습니다.
2025-09-23 17:47:47 - app.core.database.vector_connection - ERROR - vector_connection.py:225 - 벡터스토어 정보 조회 실패: (sqlalchemy.dialects.postgresql.asyncpg.ProgrammingError) <class 'asyncpg.exceptions.UndefinedTableError'>: relation "langchain_pg_embedding_documents" does not exist
[SQL: 
                    SELECT
                        COUNT(*) as document_count,
                        pg_size_pretty(pg_total_relation_size('langchain_pg_embedding_documents')) as table_size
                    FROM langchain_pg_embedding_documents
                ]
(Background on this error at: https://sqlalche.me/e/20/f405)
